Workbook
Name Ano: Calc!$B$1
Name catFixa: Cadastro!$G$9
Name catGrupo: Cadastro!$G$6
Name catPrev: Cadastro!$G$8
Name catSub: Cadastro!$G$7
Name conMes: Contas!$B$9
Name DiaVenc: Calc!$B$3
Name frmCat: Cadastro!$C$7
Name frmData: Cadastro!$C$6
Name frmDesc: Cadastro!$C$9
Name frmPag: Cadastro!$C$10
Name frmResp: Cadastro!$C$11
Name frmValor: Cadastro!$C$8
Name gCat: Calc!$B$21:INDEX(Calc!$B$21:$B$40,MAX(1,Calc!$B$19))
Name gPrev: Calc!$F$21:INDEX(Calc!$F$21:$F$40,MAX(1,Calc!$B$19))
Name gReal: Calc!$G$21:INDEX(Calc!$G$21:$G$40,MAX(1,Calc!$B$19))
Name ListaCategorias: tbCategorias[Lista]
Name ListaGrupos: Categorias!$G$4:$G$40
Name ListaMetas: tbMetas[Meta]
Name metData: Metas!$E$9
Name metSel: Metas!$B$9
Name metValor: Metas!$D$9
Name msgStatus: Cadastro!$J$19
Name nmAcum: tbMetas[Acumulado]
Name nmAlvo: tbMetas[Alvo]
Name nmMeta: tbMetas[Meta]
Name rFonte: Cadastro!$K$7
Name rMes: Cadastro!$K$6
Name rPrev: Cadastro!$K$8
Name rReal: Cadastro!$K$9
Name SegmentaçãodeDados_Grupo: #N/A
Name SegmentaçãodeDados_Mês_Ref: #N/A
Name SegmentaçãodeDados_Pagamento: #N/A
Name SegmentaçãodeDados_Responsável: #N/A

Sheet Dinâmicas
A4: Rótulos de Linha | B4: Gasto no mês | D4: Rótulos de Linha | E4: Gasto por grupo | G4: Rótulos de Linha | H4: Gasto | J4: Total | K4: Rótulos de Coluna
A5: 01-JAN | B5: 3361 | D5: Alimentação | E5: 840 | G5: Cartão Jhenismara | H5: 1400 | J5: Rótulos de Linha | K5: Não informado | L5: Total Geral
A6: Total Geral | B6: 3361 | D6: Cartões e Dívidas | E6: 1575 | G6: Supermercado | H6: 450 | J6: Não informado | K6: 3361 | L6: 3361
D7: Comunicação | E7: 236 | G7: Café / Almoço | H7: 250 | J7: Total Geral | K7: 3361 | L7: 3361
D8: Moradia | E8: 282 | G8: Transporte Trabalho (Matheus) | H8: 240
D9: Transporte | E9: 428 | G9: Cartão Matheus | H9: 175
D10: Total Geral | E10: 3361 | G10: Energia | H10: 150
G11: Transporte Trabalho (Jhenis) | H11: 143
G12: Restaurante | H12: 140
G13: Internet | H13: 89
G14: Água | H14: 77
G15: Total Geral | H15: 3114

Sheet Calc
A1: Ano | B1: 2025 | H1: Pix | I1: Matheus | J1: Aberta | K1: Mensal | L1: Sim
D2: =INDEX($D$5:$D$16,1) -> 1 | E2: =INDEX($D$5:$D$16,2) -> 0 | F2: =INDEX($D$5:$D$16,3) -> 0 | G2: =INDEX($D$5:$D$16,4) -> 0 | H2: =INDEX($D$5:$D$16,5) -> 0 | I2: =INDEX($D$5:$D$16,6) -> 0 | J2: =INDEX($D$5:$D$16,7) -> 0 | K2: =INDEX($D$5:$D$16,8) -> 0 | L2: =INDEX($D$5:$D$16,9) -> 0 | M2: =INDEX($D$5:$D$16,10) -> 0 | N2: =INDEX($D$5:$D$16,11) -> 0 | O2: =INDEX($D$5:$D$16,12) -> 0
A3: Dia de vencimento padrão | B3: 10 | H3: Crédito | I3: Casa
A4: Mês | B4: Rótulo | C4: Ref | D4: Filtro | E4: Renda | F4: Renda prev. | G4: Despesa | H4: Previsto | I4: gRenda | J4: gDespesa | K4: gSaldoAcum
A5: 1 | B5: JAN | C5: 01-JAN | D5: 1 | E5: =SUMIFS(tbRendas[Real],tbRendas[Mês],A5) -> 4730 | F5: =SUMIFS(tbRendas[Previsto],tbRendas[Mês],A5) -> 6678 | G5: =IFERROR(GETPIVOTDATA("Gasto no mês",Dinâmicas!$A$4,"Mês Ref",C5),0) -> 3361 | H5: =SUMPRODUCT(SUMIFS(INDEX(Orçamento!$D$5:$O$300,0,A5),Orçamento!$B$5:$B$300,$B$21:$B$40)*$C$21:$C$40*($B$21:$B$40<>"")) -> 19582.3 | I5: =IF(D5=1,E5,NA()) -> 4730 | J5: =IF(D5=1,G5,NA()) -> 3361 | K5: =IF(D5=1,SUMPRODUCT($D$5:D5,$E$5:E5)-SUMPRODUCT($D$5:D5,$G$5:G5),NA()) -> 1369
A6: 2 | B6: FEV | C6: 02-FEV | D6: 0 | E6: =SUMIFS(tbRendas[Real],tbRendas[Mês],A6) -> 4440 | F6: =SUMIFS(tbRendas[Previsto],tbRendas[Mês],A6) -> 4898 | G6: =IFERROR(GETPIVOTDATA("Gasto no mês",Dinâmicas!$A$4,"Mês Ref",C6),0) -> 0 | H6: =SUMPRODUCT(SUMIFS(INDEX(Orçamento!$D$5:$O$300,0,A6),Orçamento!$B$5:$B$300,$B$21:$B$40)*$C$21:$C$40*($B$21:$B$40<>"")) -> 12013.3 | I6: =IF(D6=1,E6,NA()) -> #N/A | J6: =IF(D6=1,G6,NA()) -> #N/A | K6: =IF(D6=1,SUMPRODUCT($D$5:D6,$E$5:E6)-SUMPRODUCT($D$5:D6,$G$5:G6),NA()) -> #N/A
A7: 3 | B7: MAR | C7: 03-MAR | D7: 0 | E7: =SUMIFS(tbRendas[Real],tbRendas[Mês],A7) -> 4440 | F7: =SUMIFS(tbRendas[Previsto],tbRendas[Mês],A7) -> 4898 | G7: =IFERROR(GETPIVOTDATA("Gasto no mês",Dinâmicas!$A$4,"Mês Ref",C7),0) -> 0 | H7: =SUMPRODUCT(SUMIFS(INDEX(Orçamento!$D$5:$O$300,0,A7),Orçamento!$B$5:$B$300,$B$21:$B$40)*$C$21:$C$40*($B$21:$B$40<>"")) -> 12013.3 | I7: =IF(D7=1,E7,NA()) -> #N/A | J7: =IF(D7=1,G7,NA()) -> #N/A | K7: =IF(D7=1,SUMPRODUCT($D$5:D7,$E$5:E7)-SUMPRODUCT($D$5:D7,$G$5:G7),NA()) -> #N/A
A8: 4 | B8: ABR | C8: 04-ABR | D8: 0 | E8: =SUMIFS(tbRendas[Real],tbRendas[Mês],A8) -> 4440 | F8: =SUMIFS(tbRendas[Previsto],tbRendas[Mês],A8) -> 4898 | G8: =IFERROR(GETPIVOTDATA("Gasto no mês",Dinâmicas!$A$4,"Mês Ref",C8),0) -> 0 | H8: =SUMPRODUCT(SUMIFS(INDEX(Orçamento!$D$5:$O$300,0,A8),Orçamento!$B$5:$B$300,$B$21:$B$40)*$C$21:$C$40*($B$21:$B$40<>"")) -> 12013.3 | I8: =IF(D8=1,E8,NA()) -> #N/A | J8: =IF(D8=1,G8,NA()) -> #N/A | K8: =IF(D8=1,SUMPRODUCT($D$5:D8,$E$5:E8)-SUMPRODUCT($D$5:D8,$G$5:G8),NA()) -> #N/A
A9: 5 | B9: MAI | C9: 05-MAI | D9: 0 | E9: =SUMIFS(tbRendas[Real],tbRendas[Mês],A9) -> 4440 | F9: =SUMIFS(tbRendas[Previsto],tbRendas[Mês],A9) -> 4898 | G9: =IFERROR(GETPIVOTDATA("Gasto no mês",Dinâmicas!$A$4,"Mês Ref",C9),0) -> 0 | H9: =SUMPRODUCT(SUMIFS(INDEX(Orçamento!$D$5:$O$300,0,A9),Orçamento!$B$5:$B$300,$B$21:$B$40)*$C$21:$C$40*($B$21:$B$40<>"")) -> 12013.3 | I9: =IF(D9=1,E9,NA()) -> #N/A | J9: =IF(D9=1,G9,NA()) -> #N/A | K9: =IF(D9=1,SUMPRODUCT($D$5:D9,$E$5:E9)-SUMPRODUCT($D$5:D9,$G$5:G9),NA()) -> #N/A
A10: 6 | B10: JUN | C10: 06-JUN | D10: 0 | E10: =SUMIFS(tbRendas[Real],tbRendas[Mês],A10) -> 4440 | F10: =SUMIFS(tbRendas[Previsto],tbRendas[Mês],A10) -> 4898 | G10: =IFERROR(GETPIVOTDATA("Gasto no mês",Dinâmicas!$A$4,"Mês Ref",C10),0) -> 0 | H10: =SUMPRODUCT(SUMIFS(INDEX(Orçamento!$D$5:$O$300,0,A10),Orçamento!$B$5:$B$300,$B$21:$B$40)*$C$21:$C$40*($B$21:$B$40<>"")) -> 12013.3 | I10: =IF(D10=1,E10,NA()) -> #N/A | J10: =IF(D10=1,G10,NA()) -> #N/A | K10: =IF(D10=1,SUMPRODUCT($D$5:D10,$E$5:E10)-SUMPRODUCT($D$5:D10,$G$5:G10),NA()) -> #N/A
A11: 7 | B11: JUL | C11: 07-JUL | D11: 0 | E11: =SUMIFS(tbRendas[Real],tbRendas[Mês],A11) -> 4440 | F11: =SUMIFS(tbRendas[Previsto],tbRendas[Mês],A11) -> 4898 | G11: =IFERROR(GETPIVOTDATA("Gasto no mês",Dinâmicas!$A$4,"Mês Ref",C11),0) -> 0 | H11: =SUMPRODUCT(SUMIFS(INDEX(Orçamento!$D$5:$O$300,0,A11),Orçamento!$B$5:$B$300,$B$21:$B$40)*$C$21:$C$40*($B$21:$B$40<>"")) -> 12013.3 | I11: =IF(D11=1,E11,NA()) -> #N/A | J11: =IF(D11=1,G11,NA()) -> #N/A | K11: =IF(D11=1,SUMPRODUCT($D$5:D11,$E$5:E11)-SUMPRODUCT($D$5:D11,$G$5:G11),NA()) -> #N/A
A12: 8 | B12: AGO | C12: 08-AGO | D12: 0 | E12: =SUMIFS(tbRendas[Real],tbRendas[Mês],A12) -> 4440 | F12: =SUMIFS(tbRendas[Previsto],tbRendas[Mês],A12) -> 4898 | G12: =IFERROR(GETPIVOTDATA("Gasto no mês",Dinâmicas!$A$4,"Mês Ref",C12),0) -> 0 | H12: =SUMPRODUCT(SUMIFS(INDEX(Orçamento!$D$5:$O$300,0,A12),Orçamento!$B$5:$B$300,$B$21:$B$40)*$C$21:$C$40*($B$21:$B$40<>"")) -> 12013.3 | I12: =IF(D12=1,E12,NA()) -> #N/A | J12: =IF(D12=1,G12,NA()) -> #N/A | K12: =IF(D12=1,SUMPRODUCT($D$5:D12,$E$5:E12)-SUMPRODUCT($D$5:D12,$G$5:G12),NA()) -> #N/A
A13: 9 | B13: SET | C13: 09-SET | D13: 0 | E13: =SUMIFS(tbRendas[Real],tbRendas[Mês],A13) -> 4440 | F13: =SUMIFS(tbRendas[Previsto],tbRendas[Mês],A13) -> 4898 | G13: =IFERROR(GETPIVOTDATA("Gasto no mês",Dinâmicas!$A$4,"Mês Ref",C13),0) -> 0 | H13: =SUMPRODUCT(SUMIFS(INDEX(Orçamento!$D$5:$O$300,0,A13),Orçamento!$B$5:$B$300,$B$21:$B$40)*$C$21:$C$40*($B$21:$B$40<>"")) -> 12013.3 | I13: =IF(D13=1,E13,NA()) -> #N/A | J13: =IF(D13=1,G13,NA()) -> #N/A | K13: =IF(D13=1,SUMPRODUCT($D$5:D13,$E$5:E13)-SUMPRODUCT($D$5:D13,$G$5:G13),NA()) -> #N/A
A14: 10 | B14: OUT | C14: 10-OUT | D14: 0 | E14: =SUMIFS(tbRendas[Real],tbRendas[Mês],A14) -> 4440 | F14: =SUMIFS(tbRendas[Previsto],tbRendas[Mês],A14) -> 4898 | G14: =IFERROR(GETPIVOTDATA("Gasto no mês",Dinâmicas!$A$4,"Mês Ref",C14),0) -> 0 | H14: =SUMPRODUCT(SUMIFS(INDEX(Orçamento!$D$5:$O$300,0,A14),Orçamento!$B$5:$B$300,$B$21:$B$40)*$C$21:$C$40*($B$21:$B$40<>"")) -> 12013.3 | I14: =IF(D14=1,E14,NA()) -> #N/A | J14: =IF(D14=1,G14,NA()) -> #N/A | K14: =IF(D14=1,SUMPRODUCT($D$5:D14,$E$5:E14)-SUMPRODUCT($D$5:D14,$G$5:G14),NA()) -> #N/A
A15: 11 | B15: NOV | C15: 11-NOV | D15: 0 | E15: =SUMIFS(tbRendas[Real],tbRendas[Mês],A15) -> 4440 | F15: =SUMIFS(tbRendas[Previsto],tbRendas[Mês],A15) -> 4898 | G15: =IFERROR(GETPIVOTDATA("Gasto no mês",Dinâmicas!$A$4,"Mês Ref",C15),0) -> 0 | H15: =SUMPRODUCT(SUMIFS(INDEX(Orçamento!$D$5:$O$300,0,A15),Orçamento!$B$5:$B$300,$B$21:$B$40)*$C$21:$C$40*($B$21:$B$40<>"")) -> 12013.3 | I15: =IF(D15=1,E15,NA()) -> #N/A | J15: =IF(D15=1,G15,NA()) -> #N/A | K15: =IF(D15=1,SUMPRODUCT($D$5:D15,$E$5:E15)-SUMPRODUCT($D$5:D15,$G$5:G15),NA()) -> #N/A
A16: 12 | B16: DEZ | C16: 12-DEZ | D16: 0 | E16: =SUMIFS(tbRendas[Real],tbRendas[Mês],A16) -> 4440 | F16: =SUMIFS(tbRendas[Previsto],tbRendas[Mês],A16) -> 4898 | G16: =IFERROR(GETPIVOTDATA("Gasto no mês",Dinâmicas!$A$4,"Mês Ref",C16),0) -> 0 | H16: =SUMPRODUCT(SUMIFS(INDEX(Orçamento!$D$5:$O$300,0,A16),Orçamento!$B$5:$B$300,$B$21:$B$40)*$C$21:$C$40*($B$21:$B$40<>"")) -> 12013.3 | I16: =IF(D16=1,E16,NA()) -> #N/A | J16: =IF(D16=1,G16,NA()) -> #N/A | K16: =IF(D16=1,SUMPRODUCT($D$5:D16,$E$5:E16)-SUMPRODUCT($D$5:D16,$G$5:G16),NA()) -> #N/A
A19: Qtde grupos | B19: =COUNTIF(B21:B40,"?*") -> 13
B20: Grupo | C20: Filtro | D20: Previsto | E20: Realizado | F20: gPrevisto | G20: gRealizado
B21: =IFERROR(IF(INDEX(ListaGrupos,1)=0,"",INDEX(ListaGrupos,1)),"") -> Moradia | C21: 1 | D21: =IF(B21="","",SUMPRODUCT((Orçamento!$B$5:$B$300=B21)*Orçamento!$D$5:$O$300*$D$2:$O$2)) -> 2002 | E21: =IF(B21="","",IFERROR(GETPIVOTDATA("Gasto por grupo",Dinâmicas!$D$4,"Grupo",B21),0)) -> 282 | F21: =IF(OR(B21="",C21=0),NA(),D21) -> 2002 | G21: =IF(OR(B21="",C21=0),NA(),E21) -> 282
B22: =IFERROR(IF(INDEX(ListaGrupos,2)=0,"",INDEX(ListaGrupos,2)),"") -> Alimentação | C22: 1 | D22: =IF(B22="","",SUMPRODUCT((Orçamento!$B$5:$B$300=B22)*Orçamento!$D$5:$O$300*$D$2:$O$2)) -> 830 | E22: =IF(B22="","",IFERROR(GETPIVOTDATA("Gasto por grupo",Dinâmicas!$D$4,"Grupo",B22),0)) -> 840 | F22: =IF(OR(B22="",C22=0),NA(),D22) -> 830 | G22: =IF(OR(B22="",C22=0),NA(),E22) -> 840
B23: =IFERROR(IF(INDEX(ListaGrupos,3)=0,"",INDEX(ListaGrupos,3)),"") -> Comunicação | C23: 1 | D23: =IF(B23="","",SUMPRODUCT((Orçamento!$B$5:$B$300=B23)*Orçamento!$D$5:$O$300*$D$2:$O$2)) -> 225.3 | E23: =IF(B23="","",IFERROR(GETPIVOTDATA("Gasto por grupo",Dinâmicas!$D$4,"Grupo",B23),0)) -> 236 | F23: =IF(OR(B23="",C23=0),NA(),D23) -> 225.3 | G23: =IF(OR(B23="",C23=0),NA(),E23) -> 236
B24: =IFERROR(IF(INDEX(ListaGrupos,4)=0,"",INDEX(ListaGrupos,4)),"") -> Saúde e Cuidados | C24: 1 | D24: =IF(B24="","",SUMPRODUCT((Orçamento!$B$5:$B$300=B24)*Orçamento!$D$5:$O$300*$D$2:$O$2)) -> 679 | E24: =IF(B24="","",IFERROR(GETPIVOTDATA("Gasto por grupo",Dinâmicas!$D$4,"Grupo",B24),0)) -> 0 | F24: =IF(OR(B24="",C24=0),NA(),D24) -> 679 | G24: =IF(OR(B24="",C24=0),NA(),E24) -> 0
B25: =IFERROR(IF(INDEX(ListaGrupos,5)=0,"",INDEX(ListaGrupos,5)),"") -> Vestuário | C25: 1 | D25: =IF(B25="","",SUMPRODUCT((Orçamento!$B$5:$B$300=B25)*Orçamento!$D$5:$O$300*$D$2:$O$2)) -> 39 | E25: =IF(B25="","",IFERROR(GETPIVOTDATA("Gasto por grupo",Dinâmicas!$D$4,"Grupo",B25),0)) -> 0 | F25: =IF(OR(B25="",C25=0),NA(),D25) -> 39 | G25: =IF(OR(B25="",C25=0),NA(),E25) -> 0
B26: =IFERROR(IF(INDEX(ListaGrupos,6)=0,"",INDEX(ListaGrupos,6)),"") -> Transporte | C26: 1 | D26: =IF(B26="","",SUMPRODUCT((Orçamento!$B$5:$B$300=B26)*Orçamento!$D$5:$O$300*$D$2:$O$2)) -> 916 | E26: =IF(B26="","",IFERROR(GETPIVOTDATA("Gasto por grupo",Dinâmicas!$D$4,"Grupo",B26),0)) -> 428 | F26: =IF(OR(B26="",C26=0),NA(),D26) -> 916 | G26: =IF(OR(B26="",C26=0),NA(),E26) -> 428
B27: =IFERROR(IF(INDEX(ListaGrupos,7)=0,"",INDEX(ListaGrupos,7)),"") -> Educação | C27: 1 | D27: =IF(B27="","",SUMPRODUCT((Orçamento!$B$5:$B$300=B27)*Orçamento!$D$5:$O$300*$D$2:$O$2)) -> 140 | E27: =IF(B27="","",IFERROR(GETPIVOTDATA("Gasto por grupo",Dinâmicas!$D$4,"Grupo",B27),0)) -> 0 | F27: =IF(OR(B27="",C27=0),NA(),D27) -> 140 | G27: =IF(OR(B27="",C27=0),NA(),E27) -> 0
B28: =IFERROR(IF(INDEX(ListaGrupos,8)=0,"",INDEX(ListaGrupos,8)),"") -> Lazer | C28: 1 | D28: =IF(B28="","",SUMPRODUCT((Orçamento!$B$5:$B$300=B28)*Orçamento!$D$5:$O$300*$D$2:$O$2)) -> 778 | E28: =IF(B28="","",IFERROR(GETPIVOTDATA("Gasto por grupo",Dinâmicas!$D$4,"Grupo",B28),0)) -> 0 | F28: =IF(OR(B28="",C28=0),NA(),D28) -> 778 | G28: =IF(OR(B28="",C28=0),NA(),E28) -> 0
B29: =IFERROR(IF(INDEX(ListaGrupos,9)=0,"",INDEX(ListaGrupos,9)),"") -> Casa (Artigos) | C29: 1 | D29: =IF(B29="","",SUMPRODUCT((Orçamento!$B$5:$B$300=B29)*Orçamento!$D$5:$O$300*$D$2:$O$2)) -> 0 | E29: =IF(B29="","",IFERROR(GETPIVOTDATA("Gasto por grupo",Dinâmicas!$D$4,"Grupo",B29),0)) -> 0 | F29: =IF(OR(B29="",C29=0),NA(),D29) -> 0 | G29: =IF(OR(B29="",C29=0),NA(),E29) -> 0
B30: =IFERROR(IF(INDEX(ListaGrupos,10)=0,"",INDEX(ListaGrupos,10)),"") -> Outros | C30: 1 | D30: =IF(B30="","",SUMPRODUCT((Orçamento!$B$5:$B$300=B30)*Orçamento!$D$5:$O$300*$D$2:$O$2)) -> 0 | E30: =IF(B30="","",IFERROR(GETPIVOTDATA("Gasto por grupo",Dinâmicas!$D$4,"Grupo",B30),0)) -> 0 | F30: =IF(OR(B30="",C30=0),NA(),D30) -> 0 | G30: =IF(OR(B30="",C30=0),NA(),E30) -> 0
B31: =IFERROR(IF(INDEX(ListaGrupos,11)=0,"",INDEX(ListaGrupos,11)),"") -> Cartões e Dívidas | C31: 1 | D31: =IF(B31="","",SUMPRODUCT((Orçamento!$B$5:$B$300=B31)*Orçamento!$D$5:$O$300*$D$2:$O$2)) -> 9173 | E31: =IF(B31="","",IFERROR(GETPIVOTDATA("Gasto por grupo",Dinâmicas!$D$4,"Grupo",B31),0)) -> 1575 | F31: =IF(OR(B31="",C31=0),NA(),D31) -> 9173 | G31: =IF(OR(B31="",C31=0),NA(),E31) -> 1575
B32: =IFERROR(IF(INDEX(ListaGrupos,12)=0,"",INDEX(ListaGrupos,12)),"") -> Financeiro | C32: 1 | D32: =IF(B32="","",SUMPRODUCT((Orçamento!$B$5:$B$300=B32)*Orçamento!$D$5:$O$300*$D$2:$O$2)) -> 0 | E32: =IF(B32="","",IFERROR(GETPIVOTDATA("Gasto por grupo",Dinâmicas!$D$4,"Grupo",B32),0)) -> 0 | F32: =IF(OR(B32="",C32=0),NA(),D32) -> 0 | G32: =IF(OR(B32="",C32=0),NA(),E32) -> 0
B33: =IFERROR(IF(INDEX(ListaGrupos,13)=0,"",INDEX(ListaGrupos,13)),"") -> Investimentos | C33: 1 | D33: =IF(B33="","",SUMPRODUCT((Orçamento!$B$5:$B$300=B33)*Orçamento!$D$5:$O$300*$D$2:$O$2)) -> 4800 | E33: =IF(B33="","",IFERROR(GETPIVOTDATA("Gasto por grupo",Dinâmicas!$D$4,"Grupo",B33),0)) -> 0 | F33: =IF(OR(B33="",C33=0),NA(),D33) -> 4800 | G33: =IF(OR(B33="",C33=0),NA(),E33) -> 0
B34: =IFERROR(IF(INDEX(ListaGrupos,14)=0,"",INDEX(ListaGrupos,14)),"") | C34: 0 | D34: =IF(B34="","",SUMPRODUCT((Orçamento!$B$5:$B$300=B34)*Orçamento!$D$5:$O$300*$D$2:$O$2)) | E34: =IF(B34="","",IFERROR(GETPIVOTDATA("Gasto por grupo",Dinâmicas!$D$4,"Grupo",B34),0)) | F34: =IF(OR(B34="",C34=0),NA(),D34) -> #N/A | G34: =IF(OR(B34="",C34=0),NA(),E34) -> #N/A
B35: =IFERROR(IF(INDEX(ListaGrupos,15)=0,"",INDEX(ListaGrupos,15)),"") | C35: 0 | D35: =IF(B35="","",SUMPRODUCT((Orçamento!$B$5:$B$300=B35)*Orçamento!$D$5:$O$300*$D$2:$O$2)) | E35: =IF(B35="","",IFERROR(GETPIVOTDATA("Gasto por grupo",Dinâmicas!$D$4,"Grupo",B35),0)) | F35: =IF(OR(B35="",C35=0),NA(),D35) -> #N/A | G35: =IF(OR(B35="",C35=0),NA(),E35) -> #N/A
B36: =IFERROR(IF(INDEX(ListaGrupos,16)=0,"",INDEX(ListaGrupos,16)),"") | C36: 0 | D36: =IF(B36="","",SUMPRODUCT((Orçamento!$B$5:$B$300=B36)*Orçamento!$D$5:$O$300*$D$2:$O$2)) | E36: =IF(B36="","",IFERROR(GETPIVOTDATA("Gasto por grupo",Dinâmicas!$D$4,"Grupo",B36),0)) | F36: =IF(OR(B36="",C36=0),NA(),D36) -> #N/A | G36: =IF(OR(B36="",C36=0),NA(),E36) -> #N/A
B37: =IFERROR(IF(INDEX(ListaGrupos,17)=0,"",INDEX(ListaGrupos,17)),"") | C37: 0 | D37: =IF(B37="","",SUMPRODUCT((Orçamento!$B$5:$B$300=B37)*Orçamento!$D$5:$O$300*$D$2:$O$2)) | E37: =IF(B37="","",IFERROR(GETPIVOTDATA("Gasto por grupo",Dinâmicas!$D$4,"Grupo",B37),0)) | F37: =IF(OR(B37="",C37=0),NA(),D37) -> #N/A | G37: =IF(OR(B37="",C37=0),NA(),E37) -> #N/A
B38: =IFERROR(IF(INDEX(ListaGrupos,18)=0,"",INDEX(ListaGrupos,18)),"") | C38: 0 | D38: =IF(B38="","",SUMPRODUCT((Orçamento!$B$5:$B$300=B38)*Orçamento!$D$5:$O$300*$D$2:$O$2)) | E38: =IF(B38="","",IFERROR(GETPIVOTDATA("Gasto por grupo",Dinâmicas!$D$4,"Grupo",B38),0)) | F38: =IF(OR(B38="",C38=0),NA(),D38) -> #N/A | G38: =IF(OR(B38="",C38=0),NA(),E38) -> #N/A
B39: =IFERROR(IF(INDEX(ListaGrupos,19)=0,"",INDEX(ListaGrupos,19)),"") | C39: 0 | D39: =IF(B39="","",SUMPRODUCT((Orçamento!$B$5:$B$300=B39)*Orçamento!$D$5:$O$300*$D$2:$O$2)) | E39: =IF(B39="","",IFERROR(GETPIVOTDATA("Gasto por grupo",Dinâmicas!$D$4,"Grupo",B39),0)) | F39: =IF(OR(B39="",C39=0),NA(),D39) -> #N/A | G39: =IF(OR(B39="",C39=0),NA(),E39) -> #N/A
B40: =IFERROR(IF(INDEX(ListaGrupos,20)=0,"",INDEX(ListaGrupos,20)),"") | C40: 0 | D40: =IF(B40="","",SUMPRODUCT((Orçamento!$B$5:$B$300=B40)*Orçamento!$D$5:$O$300*$D$2:$O$2)) | E40: =IF(B40="","",IFERROR(GETPIVOTDATA("Gasto por grupo",Dinâmicas!$D$4,"Grupo",B40),0)) | F40: =IF(OR(B40="",C40=0),NA(),D40) -> #N/A | G40: =IF(OR(B40="",C40=0),NA(),E40) -> #N/A
A44: Indicador | B44: Valor | C44: Texto | D44: Situação | E44: Comparação
A45: Renda | B45: =SUMPRODUCT(D5:D16,E5:E16) -> 4730 | C45: =DOLLAR(B45,0) -> R$ 4.730 | D45: =IF(B46=0,0,IF(B45>=B46,1,-1)) -> -1 | E45: =IF(B46=0,"Sem renda prevista",IF(B45>=B46,"▲ ","▼ ")&DOLLAR(ABS(B45-B46),0)&" vs previsto") -> ▼ R$ 1.948 vs previsto
...

Sheet Painel

Sheet Análise
B4: Despesas por grupo e mês | Q4: Participação e ticket médio por grupo
B6: Total | C6: Mês | Q6: Grupo | R6: Total | S6: % do total | T6: Lançamentos | U6: Ticket médio
B7: Grupo / Subcategoria | C7: 01-JAN | D7: Total Geral | Q7: Cartões e Dívidas | R7: 1575 | S7: 0.46861053 | T7: 2 | U7: 787.5
B8: Alimentação | C8: 840 | D8: 840 | Q8: Alimentação | R8: 840 | S8: 0.24992562 | T8: 3 | U8: 280
B9: Cartões e Dívidas | C9: 1575 | D9: 1575 | Q9: Transporte | R9: 428 | S9: 0.12734305 | T9: 3 | U9: 142.66667
B10: Comunicação | C10: 236 | D10: 236 | Q10: Moradia | R10: 282 | S10: 0.0839036 | T10: 3 | U10: 94
B11: Moradia | C11: 282 | D11: 282 | Q11: Comunicação | R11: 236 | S11: 0.070217197 | T11: 6 | U11: 39.333333
B12: Transporte | C12: 428 | D12: 428 | Q12: Total Geral | R12: 3361 | S12: 1 | T12: 17 | U12: 197.70588
B13: Total Geral | C13: 3361 | D13: 3361
Q22: Por responsável e forma de pagamento
Q24: Total | R24: Pagamento
Q25: Responsável | R25: Não informado | S25: Total Geral
Q26: Não informado | R26: 3361 | S26: 3361
Q27: Total Geral | R27: 3361 | S27: 3361

Sheet Cadastro
B4: Novo gasto | F4: Nova categoria | J4: Nova renda
B6: Data | C6: 46022 | F6: Grupo | J6: Mês | K6: 12
B7: Categoria | F7: Subcategoria | J7: Fonte
B8: Valor | F8: Previsto/mês | J8: Previsto
B9: Descrição | F9: Conta fixa? | G9: Não | J9: Real
B10: Pagamento
B11: Responsável
C12: =IFERROR(IF(frmCat="","","Previsto no mês "&DOLLAR(IFERROR(INDEX(Orçamento!$D$5:$O$300,MATCH(VALUE(LEFT(frmCat,FIND(" ",frmCat)-1)),Orçamento!$A$5:$A$300,0),MONTH(frmData)),0),2)&" · gasto "&DOLLAR(SUMIFS(tbLancamentos[Valor],tbLancamentos[Código],VALUE(LEFT(frmCat,FIND(" ",frmCat)-1)),tbLancamentos[Mês],MONTH(frmData)),2)),"")
B17: Importar e auditar | J17: Última ação

Sheet Contas
B8: Mês
B9: 12
B11: Vencimento | C11: Descrição | D11: Código | E11: Categoria | F11: Valor | G11: Recorrência | H11: Status | I11: Pago em | J11: Situação
E12: =IF(tbContas[[#This Row],[Código]]="","",IFERROR(INDEX(tbCategorias[Subcategoria],MATCH(tbContas[[#This Row],[Código]],tbCategorias[Código],0)),"CÓDIGO INVÁLIDO")) | J12: =IF(tbContas[[#This Row],[Descrição]]="","",IF(tbContas[[#This Row],[Status]]="Paga","Paga",IF(tbContas[[#This Row],[Vencimento]]<TODAY(),"Vencida",IF(tbContas[[#This Row],[Vencimento]]-TODAY()<=7,"Vence em 7 dias","A vencer"))))

Sheet Metas
B8: Meta | D8: Valor do aporte | E8: Data
E9: 46022
B11: Meta | C11: Código | D11: Alvo | E11: Prazo | F11: Acumulado | G11: % concluído | H11: Falta | I11: Aporte mensal | J11: Situação
B12: Caixa de Emergência | C12: 1 | D12: 1800 | E12: 46022 | F12: =IF(tbMetas[[#This Row],[Código]]="",0,SUMIFS(tbLancamentos[Valor],tbLancamentos[Código],tbMetas[[#This Row],[Código]])) -> 0 | G12: =IFERROR(MIN(1,tbMetas[[#This Row],[Acumulado]]/tbMetas[[#This Row],[Alvo]]),0) -> 0 | H12: =MAX(0,N(tbMetas[[#This Row],[Alvo]])-tbMetas[[#This Row],[Acumulado]]) -> 1800 | I12: =IF(tbMetas[[#This Row],[Meta]]="",0,IF(tbMetas[[#This Row],[Prazo]]<=TODAY(),tbMetas[[#This Row],[Falta]],tbMetas[[#This Row],[Falta]]/(DATEDIF(TODAY(),tbMetas[[#This Row],[Prazo]],"m")+1))) -> 1800 | J12: =IF(tbMetas[[#This Row],[Meta]]="","",IF(tbMetas[[#This Row],[Acumulado]]>=tbMetas[[#This Row],[Alvo]],"Concluída",IF(tbMetas[[#This Row],[Prazo]]<TODAY(),"Atrasada","Em andamento"))) -> Atrasada
B13: Emergência Casa | C13: 5 | D13: 1440 | E13: 46022 | F13: =IF(tbMetas[[#This Row],[Código]]="",0,SUMIFS(tbLancamentos[Valor],tbLancamentos[Código],tbMetas[[#This Row],[Código]])) -> 0 | G13: =IFERROR(MIN(1,tbMetas[[#This Row],[Acumulado]]/tbMetas[[#This Row],[Alvo]]),0) -> 0 | H13: =MAX(0,N(tbMetas[[#This Row],[Alvo]])-tbMetas[[#This Row],[Acumulado]]) -> 1440 | I13: =IF(tbMetas[[#This Row],[Meta]]="",0,IF(tbMetas[[#This Row],[Prazo]]<=TODAY(),tbMetas[[#This Row],[Falta]],tbMetas[[#This Row],[Falta]]/(DATEDIF(TODAY(),tbMetas[[#This Row],[Prazo]],"m")+1))) -> 1440 | J13: =IF(tbMetas[[#This Row],[Meta]]="","",IF(tbMetas[[#This Row],[Acumulado]]>=tbMetas[[#This Row],[Alvo]],"Concluída",IF(tbMetas[[#This Row],[Prazo]]<TODAY(),"Atrasada","Em andamento"))) -> Atrasada
B14: Renda Variável | C14: 34 | D14: 14400 | E14: 46022 | F14: =IF(tbMetas[[#This Row],[Código]]="",0,SUMIFS(tbLancamentos[Valor],tbLancamentos[Código],tbMetas[[#This Row],[Código]])) -> 0 | G14: =IFERROR(MIN(1,tbMetas[[#This Row],[Acumulado]]/tbMetas[[#This Row],[Alvo]]),0) -> 0 | H14: =MAX(0,N(tbMetas[[#This Row],[Alvo]])-tbMetas[[#This Row],[Acumulado]]) -> 14400 | I14: =IF(tbMetas[[#This Row],[Meta]]="",0,IF(tbMetas[[#This Row],[Prazo]]<=TODAY(),tbMetas[[#This Row],[Falta]],tbMetas[[#This Row],[Falta]]/(DATEDIF(TODAY(),tbMetas[[#This Row],[Prazo]],"m")+1))) -> 14400 | J14: =IF(tbMetas[[#This Row],[Meta]]="","",IF(tbMetas[[#This Row],[Acumulado]]>=tbMetas[[#This Row],[Alvo]],"Concluída",IF(tbMetas[[#This Row],[Prazo]]<TODAY(),"Atrasada","Em andamento"))) -> Atrasada
B15: Fundos Imobiliários | C15: 35 | D15: 14400 | E15: 46022 | F15: =IF(tbMetas[[#This Row],[Código]]="",0,SUMIFS(tbLancamentos[Valor],tbLancamentos[Código],tbMetas[[#This Row],[Código]])) -> 0 | G15: =IFERROR(MIN(1,tbMetas[[#This Row],[Acumulado]]/tbMetas[[#This Row],[Alvo]]),0) -> 0 | H15: =MAX(0,N(tbMetas[[#This Row],[Alvo]])-tbMetas[[#This Row],[Acumulado]]) -> 14400 | I15: =IF(tbMetas[[#This Row],[Meta]]="",0,IF(tbMetas[[#This Row],[Prazo]]<=TODAY(),tbMetas[[#This Row],[Falta]],tbMetas[[#This Row],[Falta]]/(DATEDIF(TODAY(),tbMetas[[#This Row],[Prazo]],"m")+1))) -> 14400 | J15: =IF(tbMetas[[#This Row],[Meta]]="","",IF(tbMetas[[#This Row],[Acumulado]]>=tbMetas[[#This Row],[Alvo]],"Concluída",IF(tbMetas[[#This Row],[Prazo]]<TODAY(),"Atrasada","Em andamento"))) -> Atrasada
B16: Ações Baixo Risco | C16: 36 | D16: 14400 | E16: 46022 | F16: =IF(tbMetas[[#This Row],[Código]]="",0,SUMIFS(tbLancamentos[Valor],tbLancamentos[Código],tbMetas[[#This Row],[Código]])) -> 0 | G16: =IFERROR(MIN(1,tbMetas[[#This Row],[Acumulado]]/tbMetas[[#This Row],[Alvo]]),0) -> 0 | H16: =MAX(0,N(tbMetas[[#This Row],[Alvo]])-tbMetas[[#This Row],[Acumulado]]) -> 14400 | I16: =IF(tbMetas[[#This Row],[Meta]]="",0,IF(tbMetas[[#This Row],[Prazo]]<=TODAY(),tbMetas[[#This Row],[Falta]],tbMetas[[#This Row],[Falta]]/(DATEDIF(TODAY(),tbMetas[[#This Row],[Prazo]],"m")+1))) -> 14400 | J16: =IF(tbMetas[[#This Row],[Meta]]="","",IF(tbMetas[[#This Row],[Acumulado]]>=tbMetas[[#This Row],[Alvo]],"Concluída",IF(tbMetas[[#This Row],[Prazo]]<TODAY(),"Atrasada","Em andamento"))) -> Atrasada
B17: Ações Alto Risco | C17: 37 | D17: 14400 | E17: 46022 | F17: =IF(tbMetas[[#This Row],[Código]]="",0,SUMIFS(tbLancamentos[Valor],tbLancamentos[Código],tbMetas[[#This Row],[Código]])) -> 0 | G17: =IFERROR(MIN(1,tbMetas[[#This Row],[Acumulado]]/tbMetas[[#This Row],[Alvo]]),0) -> 0 | H17: =MAX(0,N(tbMetas[[#This Row],[Alvo]])-tbMetas[[#This Row],[Acumulado]]) -> 14400 | I17: =IF(tbMetas[[#This Row],[Meta]]="",0,IF(tbMetas[[#This Row],[Prazo]]<=TODAY(),tbMetas[[#This Row],[Falta]],tbMetas[[#This Row],[Falta]]/(DATEDIF(TODAY(),tbMetas[[#This Row],[Prazo]],"m")+1))) -> 14400 | J17: =IF(tbMetas[[#This Row],[Meta]]="","",IF(tbMetas[[#This Row],[Acumulado]]>=tbMetas[[#This Row],[Alvo]],"Concluída",IF(tbMetas[[#This Row],[Prazo]]<TODAY(),"Atrasada","Em andamento"))) -> Atrasada

Sheet Lançamentos
A4: Data | B4: Mês | C4: Código | D4: Grupo | E4: Subcategoria | F4: Descrição | G4: Valor | H4: Pagamento | I4: Responsável | J4: Origem | K4: Mês Ref
A5: 45658 | B5: =IF(tbLancamentos[[#This Row],[Data]]="","",MONTH(tbLancamentos[[#This Row],[Data]])) -> 1 | C5: 6 | D5: =IF(tbLancamentos[[#This Row],[Código]]="","",IFERROR(INDEX(tbCategorias[Grupo],MATCH(tbLancamentos[[#This Row],[Código]],tbCategorias[Código],0)),"CÓDIGO INVÁLIDO")) -> Moradia | E5: =IF(tbLancamentos[[#This Row],[Código]]="","",IFERROR(INDEX(tbCategorias[Subcategoria],MATCH(tbLancamentos[[#This Row],[Código]],tbCategorias[Código],0)),"CÓDIGO INVÁLIDO")) -> Energia | F5: Energia – valor mensal | G5: 150 | J5: Migrado | K5: =IF(tbLancamentos[[#This Row],[Data]]="","",TEXT(tbLancamentos[[#This Row],[Mês]],"00")&"-"&CHOOSE(tbLancamentos[[#This Row],[Mês]],"JAN","FEV","MAR","ABR","MAI","JUN","JUL","AGO","SET","OUT","NOV","DEZ")) -> 01-JAN
A6: 45658 | B6: =IF(tbLancamentos[[#This Row],[Data]]="","",MONTH(tbLancamentos[[#This Row],[Data]])) -> 1 | C6: 7 | D6: =IF(tbLancamentos[[#This Row],[Código]]="","",IFERROR(INDEX(tbCategorias[Grupo],MATCH(tbLancamentos[[#This Row],[Código]],tbCategorias[Código],0)),"CÓDIGO INVÁLIDO")) -> Moradia | E6: =IF(tbLancamentos[[#This Row],[Código]]="","",IFERROR(INDEX(tbCategorias[Subcategoria],MATCH(tbLancamentos[[#This Row],[Código]],tbCategorias[Código],0)),"CÓDIGO INVÁLIDO")) -> Água | F6: Água – valor mensal | G6: 77 | J6: Migrado | K6: =IF(tbLancamentos[[#This Row],[Data]]="","",TEXT(tbLancamentos[[#This Row],[Mês]],"00")&"-"&CHOOSE(tbLancamentos[[#This Row],[Mês]],"JAN","FEV","MAR","ABR","MAI","JUN","JUL","AGO","SET","OUT","NOV","DEZ")) -> 01-JAN
A7: 45658 | B7: =IF(tbLancamentos[[#This Row],[Data]]="","",MONTH(tbLancamentos[[#This Row],[Data]])) -> 1 | C7: 8 | D7: =IF(tbLancamentos[[#This Row],[Código]]="","",IFERROR(INDEX(tbCategorias[Grupo],MATCH(tbLancamentos[[#This Row],[Código]],tbCategorias[Código],0)),"CÓDIGO INVÁLIDO")) -> Moradia | E7: =IF(tbLancamentos[[#This Row],[Código]]="","",IFERROR(INDEX(tbCategorias[Subcategoria],MATCH(tbLancamentos[[#This Row],[Código]],tbCategorias[Código],0)),"CÓDIGO INVÁLIDO")) -> Gás | F7: Gás – valor mensal | G7: 55 | J7: Migrado | K7: =IF(tbLancamentos[[#This Row],[Data]]="","",TEXT(tbLancamentos[[#This Row],[Mês]],"00")&"-"&CHOOSE(tbLancamentos[[#This Row],[Mês]],"JAN","FEV","MAR","ABR","MAI","JUN","JUL","AGO","SET","OUT","NOV","DEZ")) -> 01-JAN
A8: 45658 | B8: =IF(tbLancamentos[[#This Row],[Data]]="","",MONTH(tbLancamentos[[#This Row],[Data]])) -> 1 | C8: 11 | D8: =IF(tbLancamentos[[#This Row],[Código]]="","",IFERROR(INDEX(tbCategorias[Grupo],MATCH(tbLancamentos[[#This Row],[Código]],tbCategorias[Código],0)),"CÓDIGO INVÁLIDO")) -> Alimentação | E8: =IF(tbLancamentos[[#This Row],[Código]]="","",IFERROR(INDEX(tbCategorias[Subcategoria],MATCH(tbLancamentos[[#This Row],[Código]],tbCategorias[Código],0)),"CÓDIGO INVÁLIDO")) -> Supermercado | F8: Supermercado – valor mensal | G8: 450 | J8: Migrado | K8: =IF(tbLancamentos[[#This Row],[Data]]="","",TEXT(tbLancamentos[[#This Row],[Mês]],"00")&"-"&CHOOSE(tbLancamentos[[#This Row],[Mês]],"JAN","FEV","MAR","ABR","MAI","JUN","JUL","AGO","SET","OUT","NOV","DEZ")) -> 01-JAN
A9: 45658 | B9: =IF(tbLancamentos[[#This Row],[Data]]="","",MONTH(tbLancamentos[[#This Row],[Data]])) -> 1 | C9: 12 | D9: =IF(tbLancamentos[[#This Row],[Código]]="","",IFERROR(INDEX(tbCategorias[Grupo],MATCH(tbLancamentos[[#This Row],[Código]],tbCategorias[Código],0)),"CÓDIGO INVÁLIDO")) -> Alimentação | E9: =IF(tbLancamentos[[#This Row],[Código]]="","",IFERROR(INDEX(tbCategorias[Subcategoria],MATCH(tbLancamentos[[#This Row],[Código]],tbCategorias[Código],0)),"CÓDIGO INVÁLIDO")) -> Restaurante | F9: Restaurante – valor mensal | G9: 140 | J9: Migrado | K9: =IF(tbLancamentos[[#This Row],[Data]]="","",TEXT(tbLancamentos[[#This Row],[Mês]],"00")&"-"&CHOOSE(tbLancamentos[[#This Row],[Mês]],"JAN","FEV","MAR","ABR","MAI","JUN","JUL","AGO","SET","OUT","NOV","DEZ")) -> 01-JAN
A10: 45658 | B10: =IF(tbLancamentos[[#This Row],[Data]]="","",MONTH(tbLancamentos[[#This Row],[Data]])) -> 1 | C10: 13 | D10: =IF(tbLancamentos[[#This Row],[Código]]="","",IFERROR(INDEX(tbCategorias[Grupo],MATCH(tbLancamentos[[#This Row],[Código]],tbCategorias[Código],0)),"CÓDIGO INVÁLIDO")) -> Alimentação | E10: =IF(tbLancamentos[[#This Row],[Código]]="","",IFERROR(INDEX(tbCategorias[Subcategoria],MATCH(tbLancamentos[[#This Row],[Código]],tbCategorias[Código],0)),"CÓDIGO INVÁLIDO")) -> Café / Almoço | F10: Café / Almoço – valor mensal | G10: 250 | J10: Migrado | K10: =IF(tbLancamentos[[#This Row],[Data]]="","",TEXT(tbLancamentos[[#This Row],[Mês]],"00")&"-"&CHOOSE(tbLancamentos[[#This Row],[Mês]],"JAN","FEV","MAR","ABR","MAI","JUN","JUL","AGO","SET","OUT","NOV","DEZ")) -> 01-JAN
A11: 45658 | B11: =IF(tbLancamentos[[#This Row],[Data]]="","",MONTH(tbLancamentos[[#This Row],[Data]])) -> 1 | C11: 15 | D11: =IF(tbLancamentos[[#This Row],[Código]]="","",IFERROR(INDEX(tbCategorias[Grupo],MATCH(tbLancamentos[[#This Row],[Código]],tbCategorias[Código],0)),"CÓDIGO INVÁLIDO")) -> Comunicação | E11: =IF(tbLancamentos[[#This Row],[Código]]="","",IFERROR(INDEX(tbCategorias[Subcategoria],MATCH(tbLancamentos[[#This Row],[Código]],tbCategorias[Código],0)),"CÓDIGO INVÁLIDO")) -> Celular | F11: Celular – valor mensal | G11: 45 | J11: Migrado | K11: =IF(tbLancamentos[[#This Row],[Data]]="","",TEXT(tbLancamentos[[#This Row],[Mês]],"00")&"-"&CHOOSE(tbLancamentos[[#This Row],[Mês]],"JAN","FEV","MAR","ABR","MAI","JUN","JUL","AGO","SET","OUT","NOV","DEZ")) -> 01-JAN
A12: 45658 | B12: =IF(tbLancamentos[[#This Row],[Data]]="","",MONTH(tbLancamentos[[#This Row],[Data]])) -> 1 | C12: 16 | D12: =IF(tbLancamentos[[#This Row],[Código]]="","",IFERROR(INDEX(tbCategorias[Grupo],MATCH(tbLancamentos[[#This Row],[Código]],tbCategorias[Código],0)),"CÓDIGO INVÁLIDO")) -> Comunicação | E12: =IF(tbLancamentos[[#This Row],[Código]]="","",IFERROR(INDEX(tbCategorias[Subcategoria],MATCH(tbLancamentos[[#This Row],[Código]],tbCategorias[Código],0)),"CÓDIGO INVÁLIDO")) -> Internet | F12: Internet – valor mensal | G12: 89 | J12: Migrado | K12: =IF(tbLancamentos[[#This Row],[Data]]="","",TEXT(tbLancamentos[[#This Row],[Mês]],"00")&"-"&CHOOSE(tbLancamentos[[#This Row],[Mês]],"JAN","FEV","MAR","ABR","MAI","JUN","JUL","AGO","SET","OUT","NOV","DEZ")) -> 01-JAN
A13: 45658 | B13: =IF(tbLancamentos[[#This Row],[Data]]="","",MONTH(tbLancamentos[[#This Row],[Data]])) -> 1 | C13: 17 | D13: =IF(tbLancamentos[[#This Row],[Código]]="","",IFERROR(INDEX(tbCategorias[Grupo],MATCH(tbLancamentos[[#This Row],[Código]],tbCategorias[Código],0)),"CÓDIGO INVÁLIDO")) -> Comunicação | E13: =IF(tbLancamentos[[#This Row],[Código]]="","",IFERROR(INDEX(tbCategorias[Subcategoria],MATCH(tbLancamentos[[#This Row],[Código]],tbCategorias[Código],0)),"CÓDIGO INVÁLIDO")) -> Streaming (outros) | F13: Streaming (outros) – valor mensal | G13: 24 | J13: Migrado | K13: =IF(tbLancamentos[[#This Row],[Data]]="","",TEXT(tbLancamentos[[#This Row],[Mês]],"00")&"-"&CHOOSE(tbLancamentos[[#This Row],[Mês]],"JAN","FEV","MAR","ABR","MAI","JUN","JUL","AGO","SET","OUT","NOV","DEZ")) -> 01-JAN
A14: 45658 | B14: =IF(tbLancamentos[[#This Row],[Data]]="","",MONTH(tbLancamentos[[#This Row],[Data]])) -> 1 | C14: 18 | D14: =IF(tbLancamentos[[#This Row],[Código]]="","",IFERROR(INDEX(tbCategorias[Grupo],MATCH(tbLancamentos[[#This Row],[Código]],tbCategorias[Código],0)),"CÓDIGO INVÁLIDO")) -> Comunicação | E14: =IF(tbLancamentos[[#This Row],[Código]]="","",IFERROR(INDEX(tbCategorias[Subcategoria],MATCH(tbLancamentos[[#This Row],[Código]],tbCategorias[Código],0)),"CÓDIGO INVÁLIDO")) -> Netflix | F14: Netflix – valor mensal | G14: 22 | J14: Migrado | K14: =IF(tbLancamentos[[#This Row],[Data]]="","",TEXT(tbLancamentos[[#This Row],[Mês]],"00")&"-"&CHOOSE(tbLancamentos[[#This Row],[Mês]],"JAN","FEV","MAR","ABR","MAI","JUN","JUL","AGO","SET","OUT","NOV","DEZ")) -> 01-JAN
A15: 45658 | B15: =IF(tbLancamentos[[#This Row],[Data]]="","",MONTH(tbLancamentos[[#This Row],[Data]])) -> 1 | C15: 19 | D15: =IF(tbLancamentos[[#This Row],[Código]]="","",IFERROR(INDEX(tbCategorias[Grupo],MATCH(tbLancamentos[[#This Row],[Código]],tbCategorias[Código],0)),"CÓDIGO INVÁLIDO")) -> Comunicação | E15: =IF(tbLancamentos[[#This Row],[Código]]="","",IFERROR(INDEX(tbCategorias[Subcategoria],MATCH(tbLancamentos[[#This Row],[Código]],tbCategorias[Código],0)),"CÓDIGO INVÁLIDO")) -> Amazon Prime | F15: Amazon Prime – valor mensal | G15: 11 | J15: Migrado | K15: =IF(tbLancamentos[[#This Row],[Data]]="","",TEXT(tbLancamentos[[#This Row],[Mês]],"00")&"-"&CHOOSE(tbLancamentos[[#This Row],[Mês]],"JAN","FEV","MAR","ABR","MAI","JUN","JUL","AGO","SET","OUT","NOV","DEZ")) -> 01-JAN
A16: 45658 | B16: =IF(tbLancamentos[[#This Row],[Data]]="","",MONTH(tbLancamentos[[#This Row],[Data]])) -> 1 | C16: 20 | D16: =IF(tbLancamentos[[#This Row],[Código]]="","",IFERROR(INDEX(tbCategorias[Grupo],MATCH(tbLancamentos[[#This Row],[Código]],tbCategorias[Código],0)),"CÓDIGO INVÁLIDO")) -> Comunicação | E16: =IF(tbLancamentos[[#This Row],[Código]]="","",IFERROR(INDEX(tbCategorias[Subcategoria],MATCH(tbLancamentos[[#This Row],[Código]],tbCategorias[Código],0)),"CÓDIGO INVÁLIDO")) -> Max | F16: Max – valor mensal | G16: 45 | J16: Migrado | K16: =IF(tbLancamentos[[#This Row],[Data]]="","",TEXT(tbLancamentos[[#This Row],[Mês]],"00")&"-"&CHOOSE(tbLancamentos[[#This Row],[Mês]],"JAN","FEV","MAR","ABR","MAI","JUN","JUL","AGO","SET","OUT","NOV","DEZ")) -> 01-JAN
... A208: 45992 | B208: =IF(tbLancamentos[[#This Row],[Data]]="","",MONTH(tbLancamentos[[#This Row],[Data]])) -> 12 | C208: 9 | D208: =IF(tbLancamentos[[#This Row],[Código]]="","",IFERROR(INDEX(tbCategorias[Grupo],MATCH(tbLancamentos[[#This Row],[Código]],tbCategorias[Código],0)),"CÓDIGO INVÁLIDO")) -> Cartões e Dívidas | E208: =IF(tbLancamentos[[#This Row],[Código]]="","",IFERROR(INDEX(tbCategorias[Subcategoria],MATCH(tbLancamentos[[#This Row],[Código]],tbCategorias[Código],0)),"CÓDIGO INVÁLIDO")) -> Cartão Matheus | F208: Cartão Matheus – valor mensal | G208: 175 | J208: Migrado | K208: =IF(tbLancamentos[[#This Row],[Data]]="","",TEXT(tbLancamentos[[#This Row],[Mês]],"00")&"-"&CHOOSE(tbLancamentos[[#This Row],[Mês]],"JAN","FEV","MAR","ABR","MAI","JUN","JUL","AGO","SET","OUT","NOV","DEZ")) -> 12-DEZ

Sheet Orçamento
A4: Código | B4: Grupo | C4: Subcategoria | D4: JAN | E4: FEV | F4: MAR | G4: ABR | H4: MAI | I4: JUN | J4: JUL | K4: AGO | L4: SET | M4: OUT | N4: NOV | O4: DEZ | P4: Total Ano
A5: 1 | B5: =IFERROR(INDEX(Categorias!$B$4:$B$300,MATCH($A5,Categorias!$A$4:$A$300,0)),"CÓDIGO INVÁLIDO") -> Moradia | C5: =IFERROR(INDEX(Categorias!$C$4:$C$300,MATCH($A5,Categorias!$A$4:$A$300,0)),"CÓDIGO INVÁLIDO") -> Caixa de Emergência | D5: 150 | E5: 150 | F5: 150 | G5: 150 | H5: 150 | I5: 150 | J5: 150 | K5: 150 | L5: 150 | M5: 150 | N5: 150 | O5: 150 | P5: =SUM(D5:O5) -> 1800
A6: 2 | B6: =IFERROR(INDEX(Categorias!$B$4:$B$300,MATCH($A6,Categorias!$A$4:$A$300,0)),"CÓDIGO INVÁLIDO") -> Moradia | C6: =IFERROR(INDEX(Categorias!$C$4:$C$300,MATCH($A6,Categorias!$A$4:$A$300,0)),"CÓDIGO INVÁLIDO") -> Despesas Fixas Inevitáveis | D6: 1200 | E6: 1200 | F6: 1200 | G6: 1200 | H6: 1200 | I6: 1200 | J6: 1200 | K6: 1200 | L6: 1200 | M6: 1200 | N6: 1200 | O6: 1200 | P6: =SUM(D6:O6) -> 14400
A7: 3 | B7: =IFERROR(INDEX(Categorias!$B$4:$B$300,MATCH($A7,Categorias!$A$4:$A$300,0)),"CÓDIGO INVÁLIDO") -> Moradia | C7: =IFERROR(INDEX(Categorias!$C$4:$C$300,MATCH($A7,Categorias!$A$4:$A$300,0)),"CÓDIGO INVÁLIDO") -> DAS (Jhenis) | D7: 250 | E7: 250 | F7: 250 | G7: 250 | H7: 250 | I7: 250 | J7: 250 | K7: 250 | L7: 250 | M7: 250 | N7: 250 | O7: 250 | P7: =SUM(D7:O7) -> 3000
A8: 5 | B8: =IFERROR(INDEX(Categorias!$B$4:$B$300,MATCH($A8,Categorias!$A$4:$A$300,0)),"CÓDIGO INVÁLIDO") -> Moradia | C8: =IFERROR(INDEX(Categorias!$C$4:$C$300,MATCH($A8,Categorias!$A$4:$A$300,0)),"CÓDIGO INVÁLIDO") -> Emergência Casa | D8: 120 | E8: 120 | F8: 120 | G8: 120 | H8: 120 | I8: 120 | J8: 120 | K8: 120 | L8: 120 | M8: 120 | N8: 120 | O8: 120 | P8: =SUM(D8:O8) -> 1440
A9: 6 | B9: =IFERROR(INDEX(Categorias!$B$4:$B$300,MATCH($A9,Categorias!$A$4:$A$300,0)),"CÓDIGO INVÁLIDO") -> Moradia | C9: =IFERROR(INDEX(Categorias!$C$4:$C$300,MATCH($A9,Categorias!$A$4:$A$300,0)),"CÓDIGO INVÁLIDO") -> Energia | D9: 150 | E9: 150 | F9: 150 | G9: 150 | H9: 150 | I9: 150 | J9: 150 | K9: 150 | L9: 150 | M9: 150 | N9: 150 | O9: 150 | P9: =SUM(D9:O9) -> 1800
A10: 7 | B10: =IFERROR(INDEX(Categorias!$B$4:$B$300,MATCH($A10,Categorias!$A$4:$A$300,0)),"CÓDIGO INVÁLIDO") -> Moradia | C10: =IFERROR(INDEX(Categorias!$C$4:$C$300,MATCH($A10,Categorias!$A$4:$A$300,0)),"CÓDIGO INVÁLIDO") -> Água | D10: 77 | E10: 77 | F10: 77 | G10: 77 | H10: 77 | I10: 77 | J10: 77 | K10: 77 | L10: 77 | M10: 77 | N10: 77 | O10: 77 | P10: =SUM(D10:O10) -> 924
A11: 8 | B11: =IFERROR(INDEX(Categorias!$B$4:$B$300,MATCH($A11,Categorias!$A$4:$A$300,0)),"CÓDIGO INVÁLIDO") -> Moradia | C11: =IFERROR(INDEX(Categorias!$C$4:$C$300,MATCH($A11,Categorias!$A$4:$A$300,0)),"CÓDIGO INVÁLIDO") -> Gás | D11: 55 | E11: 55 | F11: 55 | G11: 55 | H11: 55 | I11: 55 | J11: 55 | K11: 55 | L11: 55 | M11: 55 | N11: 55 | O11: 55 | P11: =SUM(D11:O11) -> 660
A12: 10 | B12: =IFERROR(INDEX(Categorias!$B$4:$B$300,MATCH($A12,Categorias!$A$4:$A$300,0)),"CÓDIGO INVÁLIDO") -> Moradia | C12: =IFERROR(INDEX(Categorias!$C$4:$C$300,MATCH($A12,Categorias!$A$4:$A$300,0)),"CÓDIGO INVÁLIDO") -> Outras Despesas | D12: 0 | E12: 0 | F12: 0 | G12: 0 | H12: 0 | I12: 0 | J12: 0 | K12: 0 | L12: 0 | M12: 0 | N12: 0 | O12: 0 | P12: =SUM(D12:O12) -> 0
A13: 11 | B13: =IFERROR(INDEX(Categorias!$B$4:$B$300,MATCH($A13,Categorias!$A$4:$A$300,0)),"CÓDIGO INVÁLIDO") -> Alimentação | C13: =IFERROR(INDEX(Categorias!$C$4:$C$300,MATCH($A13,Categorias!$A$4:$A$300,0)),"CÓDIGO INVÁLIDO") -> Supermercado | D13: 450 | E13: 450 | F13: 450 | G13: 450 | H13: 450 | I13: 450 | J13: 450 | K13: 450 | L13: 450 | M13: 450 | N13: 450 | O13: 450 | P13: =SUM(D13:O13) -> 5400
A14: 12 | B14: =IFERROR(INDEX(Categorias!$B$4:$B$300,MATCH($A14,Categorias!$A$4:$A$300,0)),"CÓDIGO INVÁLIDO") -> Alimentação | C14: =IFERROR(INDEX(Categorias!$C$4:$C$300,MATCH($A14,Categorias!$A$4:$A$300,0)),"CÓDIGO INVÁLIDO") -> Restaurante | D14: 140 | E14: 140 | F14: 140 | G14: 140 | H14: 140 | I14: 140 | J14: 140 | K14: 140 | L14: 140 | M14: 140 | N14: 140 | O14: 140 | P14: =SUM(D14:O14) -> 1680
A15: 13 | B15: =IFERROR(INDEX(Categorias!$B$4:$B$300,MATCH($A15,Categorias!$A$4:$A$300,0)),"CÓDIGO INVÁLIDO") -> Alimentação | C15: =IFERROR(INDEX(Categorias!$C$4:$C$300,MATCH($A15,Categorias!$A$4:$A$300,0)),"CÓDIGO INVÁLIDO") -> Café / Almoço | D15: 100 | E15: 100 | F15: 100 | G15: 100 | H15: 100 | I15: 100 | J15: 100 | K15: 100 | L15: 100 | M15: 100 | N15: 100 | O15: 100 | P15: =SUM(D15:O15) -> 1200
A16: 14 | B16: =IFERROR(INDEX(Categorias!$B$4:$B$300,MATCH($A16,Categorias!$A$4:$A$300,0)),"CÓDIGO INVÁLIDO") -> Alimentação | C16: =IFERROR(INDEX(Categorias!$C$4:$C$300,MATCH($A16,Categorias!$A$4:$A$300,0)),"CÓDIGO INVÁLIDO") -> Pedidos iFood | D16: 140 | E16: 140 | F16: 140 | G16: 140 | H16: 140 | I16: 140 | J16: 140 | K16: 140 | L16: 140 | M16: 140 | N16: 140 | O16: 140 | P16: =SUM(D16:O16) -> 1680
... A78: 37 | B78: =IFERROR(INDEX(Categorias!$B$4:$B$300,MATCH($A78,Categorias!$A$4:$A$300,0)),"CÓDIGO INVÁLIDO") -> Investimentos | C78: =IFERROR(INDEX(Categorias!$C$4:$C$300,MATCH($A78,Categorias!$A$4:$A$300,0)),"CÓDIGO INVÁLIDO") -> Ações Alto Risco | D78: 1200 | E78: 1200 | F78: 1200 | G78: 1200 | H78: 1200 | I78: 1200 | J78: 1200 | K78: 1200 | L78: 1200 | M78: 1200 | N78: 1200 | O78: 1200 | P78: =SUM(D78:O78) -> 14400
C79: TOTAL PREVISTO | D79: =SUM(D5:D78) -> 19582.3 | E79: =SUM(E5:E78) -> 12013.3 | F79: =SUM(F5:F78) -> 12013.3 | G79: =SUM(G5:G78) -> 12013.3 | H79: =SUM(H5:H78) -> 12013.3 | I79: =SUM(I5:I78) -> 12013.3 | J79: =SUM(J5:J78) -> 12013.3 | K79: =SUM(K5:K78) -> 12013.3 | ... P79: =SUM(P5:P78) -> 151728.6

Sheet Rendas
A3: Mês | B3: Fonte | C3: Previsto | D3: Real | E3: Diferença
A4: 1 | B4: Renda 1 | C4: 2398 | D4: 1940 | E4: =tbRendas[[#This Row],[Real]]-tbRendas[[#This Row],[Previsto]] -> -458
A5: 1 | B5: Renda 2 | C5: 2500 | D5: 2500 | E5: =tbRendas[[#This Row],[Real]]-tbRendas[[#This Row],[Previsto]] -> 0
A6: 1 | B6: Renda Extra – Comissões | C6: 1200 | D6: 150 | E6: =tbRendas[[#This Row],[Real]]-tbRendas[[#This Row],[Previsto]] -> -1050
A7: 1 | B7: Renda Extra – Projetos | C7: 580 | D7: 140 | E7: =tbRendas[[#This Row],[Real]]-tbRendas[[#This Row],[Previsto]] -> -440
A8: 2 | B8: Renda 1 | C8: 2398 | D8: 1940 | E8: =tbRendas[[#This Row],[Real]]-tbRendas[[#This Row],[Previsto]] -> -458
A9: 2 | B9: Renda 2 | C9: 2500 | D9: 2500 | E9: =tbRendas[[#This Row],[Real]]-tbRendas[[#This Row],[Previsto]] -> 0
A10: 3 | B10: Renda 1 | C10: 2398 | D10: 1940 | E10: =tbRendas[[#This Row],[Real]]-tbRendas[[#This Row],[Previsto]] -> -458
A11: 3 | B11: Renda 2 | C11: 2500 | D11: 2500 | E11: =tbRendas[[#This Row],[Real]]-tbRendas[[#This Row],[Previsto]] -> 0
A12: 4 | B12: Renda 1 | C12: 2398 | D12: 1940 | E12: =tbRendas[[#This Row],[Real]]-tbRendas[[#This Row],[Previsto]] -> -458
A13: 4 | B13: Renda 2 | C13: 2500 | D13: 2500 | E13: =tbRendas[[#This Row],[Real]]-tbRendas[[#This Row],[Previsto]] -> 0
A14: 5 | B14: Renda 1 | C14: 2398 | D14: 1940 | E14: =tbRendas[[#This Row],[Real]]-tbRendas[[#This Row],[Previsto]] -> -458
A15: 5 | B15: Renda 2 | C15: 2500 | D15: 2500 | E15: =tbRendas[[#This Row],[Real]]-tbRendas[[#This Row],[Previsto]] -> 0
... A29: 12 | B29: Renda 2 | C29: 2500 | D29: 2500 | E29: =tbRendas[[#This Row],[Real]]-tbRendas[[#This Row],[Previsto]] -> 0

Sheet Categorias
A3: Código | B3: Grupo | C3: Subcategoria | D3: Fixa | E3: Lista | G3: Grupos | I3: Palavra-chave | J3: Código | K3: Categoria
A4: 1 | B4: Moradia | C4: Caixa de Emergência | D4: Não | E4: =tbCategorias[[#This Row],[Código]]&" - "&tbCategorias[[#This Row],[Subcategoria]] -> 1 - Caixa de Emergência | G4: Moradia | I4: IFOOD | J4: 14 | K4: =IF(tbRegras[[#This Row],[Código]]="","",IFERROR(INDEX(tbCategorias[Subcategoria],MATCH(tbRegras[[#This Row],[Código]],tbCategorias[Código],0)),"CÓDIGO INVÁLIDO")) -> Pedidos iFood
A5: 2 | B5: Moradia | C5: Despesas Fixas Inevitáveis | D5: Sim | E5: =tbCategorias[[#This Row],[Código]]&" - "&tbCategorias[[#This Row],[Subcategoria]] -> 2 - Despesas Fixas Inevitáveis | G5: Alimentação | I5: RAPPI | J5: 14 | K5: =IF(tbRegras[[#This Row],[Código]]="","",IFERROR(INDEX(tbCategorias[Subcategoria],MATCH(tbRegras[[#This Row],[Código]],tbCategorias[Código],0)),"CÓDIGO INVÁLIDO")) -> Pedidos iFood
A6: 3 | B6: Moradia | C6: DAS (Jhenis) | D6: Sim | E6: =tbCategorias[[#This Row],[Código]]&" - "&tbCategorias[[#This Row],[Subcategoria]] -> 3 - DAS (Jhenis) | G6: Comunicação | I6: UBER | J6: 40 | K6: =IF(tbRegras[[#This Row],[Código]]="","",IFERROR(INDEX(tbCategorias[Subcategoria],MATCH(tbRegras[[#This Row],[Código]],tbCategorias[Código],0)),"CÓDIGO INVÁLIDO")) -> Aplicativos (Uber / 99)
A7: 5 | B7: Moradia | C7: Emergência Casa | D7: Não | E7: =tbCategorias[[#This Row],[Código]]&" - "&tbCategorias[[#This Row],[Subcategoria]] -> 5 - Emergência Casa | G7: Saúde e Cuidados | I7: 99APP | J7: 40 | K7: =IF(tbRegras[[#This Row],[Código]]="","",IFERROR(INDEX(tbCategorias[Subcategoria],MATCH(tbRegras[[#This Row],[Código]],tbCategorias[Código],0)),"CÓDIGO INVÁLIDO")) -> Aplicativos (Uber / 99)
A8: 6 | B8: Moradia | C8: Energia | D8: Sim | E8: =tbCategorias[[#This Row],[Código]]&" - "&tbCategorias[[#This Row],[Subcategoria]] -> 6 - Energia | G8: Vestuário | I8: 99 POP | J8: 40 | K8: =IF(tbRegras[[#This Row],[Código]]="","",IFERROR(INDEX(tbCategorias[Subcategoria],MATCH(tbRegras[[#This Row],[Código]],tbCategorias[Código],0)),"CÓDIGO INVÁLIDO")) -> Aplicativos (Uber / 99)
A9: 7 | B9: Moradia | C9: Água | D9: Sim | E9: =tbCategorias[[#This Row],[Código]]&" - "&tbCategorias[[#This Row],[Subcategoria]] -> 7 - Água | G9: Transporte | I9: NETFLIX | J9: 18 | K9: =IF(tbRegras[[#This Row],[Código]]="","",IFERROR(INDEX(tbCategorias[Subcategoria],MATCH(tbRegras[[#This Row],[Código]],tbCategorias[Código],0)),"CÓDIGO INVÁLIDO")) -> Netflix
A10: 8 | B10: Moradia | C10: Gás | D10: Sim | E10: =tbCategorias[[#This Row],[Código]]&" - "&tbCategorias[[#This Row],[Subcategoria]] -> 8 - Gás | G10: Educação | I10: PRIME VIDEO | J10: 19 | K10: =IF(tbRegras[[#This Row],[Código]]="","",IFERROR(INDEX(tbCategorias[Subcategoria],MATCH(tbRegras[[#This Row],[Código]],tbCategorias[Código],0)),"CÓDIGO INVÁLIDO")) -> Amazon Prime
A11: 10 | B11: Moradia | C11: Outras Despesas | D11: Não | E11: =tbCategorias[[#This Row],[Código]]&" - "&tbCategorias[[#This Row],[Subcategoria]] -> 10 - Outras Despesas | G11: Lazer | I11: AMAZON PRIME | J11: 19 | K11: =IF(tbRegras[[#This Row],[Código]]="","",IFERROR(INDEX(tbCategorias[Subcategoria],MATCH(tbRegras[[#This Row],[Código]],tbCategorias[Código],0)),"CÓDIGO INVÁLIDO")) -> Amazon Prime
A12: 11 | B12: Alimentação | C12: Supermercado | D12: Não | E12: =tbCategorias[[#This Row],[Código]]&" - "&tbCategorias[[#This Row],[Subcategoria]] -> 11 - Supermercado | G12: Casa (Artigos) | I12: HBO | J12: 20 | K12: =IF(tbRegras[[#This Row],[Código]]="","",IFERROR(INDEX(tbCategorias[Subcategoria],MATCH(tbRegras[[#This Row],[Código]],tbCategorias[Código],0)),"CÓDIGO INVÁLIDO")) -> Max
A13: 12 | B13: Alimentação | C13: Restaurante | D13: Não | E13: =tbCategorias[[#This Row],[Código]]&" - "&tbCategorias[[#This Row],[Subcategoria]] -> 12 - Restaurante | G13: Outros | I13: MAX.COM | J13: 20 | K13: =IF(tbRegras[[#This Row],[Código]]="","",IFERROR(INDEX(tbCategorias[Subcategoria],MATCH(tbRegras[[#This Row],[Código]],tbCategorias[Código],0)),"CÓDIGO INVÁLIDO")) -> Max
A14: 13 | B14: Alimentação | C14: Café / Almoço | D14: Não | E14: =tbCategorias[[#This Row],[Código]]&" - "&tbCategorias[[#This Row],[Subcategoria]] -> 13 - Café / Almoço | G14: Cartões e Dívidas | I14: SPOTIFY | J14: 17 | K14: =IF(tbRegras[[#This Row],[Código]]="","",IFERROR(INDEX(tbCategorias[Subcategoria],MATCH(tbRegras[[#This Row],[Código]],tbCategorias[Código],0)),"CÓDIGO INVÁLIDO")) -> Streaming (outros)
A15: 14 | B15: Alimentação | C15: Pedidos iFood | D15: Não | E15: =tbCategorias[[#This Row],[Código]]&" - "&tbCategorias[[#This Row],[Subcategoria]] -> 14 - Pedidos iFood | G15: Financeiro | I15: DEEZER | J15: 17 | K15: =IF(tbRegras[[#This Row],[Código]]="","",IFERROR(INDEX(tbCategorias[Subcategoria],MATCH(tbRegras[[#This Row],[Código]],tbCategorias[Código],0)),"CÓDIGO INVÁLIDO")) -> Streaming (outros)
A16: 15 | B16: Comunicação | C16: Celular | D16: Sim | E16: =tbCategorias[[#This Row],[Código]]&" - "&tbCategorias[[#This Row],[Subcategoria]] -> 15 - Celular | G16: Investimentos | I16: YOUTUBE | J16: 17 | K16: =IF(tbRegras[[#This Row],[Código]]="","",IFERROR(INDEX(tbCategorias[Subcategoria],MATCH(tbRegras[[#This Row],[Código]],tbCategorias[Código],0)),"CÓDIGO INVÁLIDO")) -> Streaming (outros)
A17: 16 | B17: Comunicação | C17: Internet | D17: Sim | E17: =tbCategorias[[#This Row],[Código]]&" - "&tbCategorias[[#This Row],[Subcategoria]] -> 16 - Internet | I17: SUPERMERC | J17: 11 | K17: =IF(tbRegras[[#This Row],[Código]]="","",IFERROR(INDEX(tbCategorias[Subcategoria],MATCH(tbRegras[[#This Row],[Código]],tbCategorias[Código],0)),"CÓDIGO INVÁLIDO")) -> Supermercado
A18: 17 | B18: Comunicação | C18: Streaming (outros) | D18: Sim | E18: =tbCategorias[[#This Row],[Código]]&" - "&tbCategorias[[#This Row],[Subcategoria]] -> 17 - Streaming (outros) | I18: ATACAD | J18: 11 | K18: =IF(tbRegras[[#This Row],[Código]]="","",IFERROR(INDEX(tbCategorias[Subcategoria],MATCH(tbRegras[[#This Row],[Código]],tbCategorias[Código],0)),"CÓDIGO INVÁLIDO")) -> Supermercado
A19: 18 | B19: Comunicação | C19: Netflix | D19: Sim | E19: =tbCategorias[[#This Row],[Código]]&" - "&tbCategorias[[#This Row],[Subcategoria]] -> 18 - Netflix | I19: ASSAI | J19: 11 | K19: =IF(tbRegras[[#This Row],[Código]]="","",IFERROR(INDEX(tbCategorias[Subcategoria],MATCH(tbRegras[[#This Row],[Código]],tbCategorias[Código],0)),"CÓDIGO INVÁLIDO")) -> Supermercado
A20: 19 | B20: Comunicação | C20: Amazon Prime | D20: Sim | E20: =tbCategorias[[#This Row],[Código]]&" - "&tbCategorias[[#This Row],[Subcategoria]] -> 19 - Amazon Prime | I20: CARREFOUR | J20: 11 | K20: =IF(tbRegras[[#This Row],[Código]]="","",IFERROR(INDEX(tbCategorias[Subcategoria],MATCH(tbRegras[[#This Row],[Código]],tbCategorias[Código],0)),"CÓDIGO INVÁLIDO")) -> Supermercado
A21: 20 | B21: Comunicação | C21: Max | D21: Sim | E21: =tbCategorias[[#This Row],[Código]]&" - "&tbCategorias[[#This Row],[Subcategoria]] -> 20 - Max | I21: PAO DE ACUCAR | J21: 11 | K21: =IF(tbRegras[[#This Row],[Código]]="","",IFERROR(INDEX(tbCategorias[Subcategoria],MATCH(tbRegras[[#This Row],[Código]],tbCategorias[Código],0)),"CÓDIGO INVÁLIDO")) -> Supermercado
A22: 21 | B22: Saúde e Cuidados | C22: Academia | D22: Sim | E22: =tbCategorias[[#This Row],[Código]]&" - "&tbCategorias[[#This Row],[Subcategoria]] -> 21 - Academia | I22: HORTIFRUTI | J22: 11 | K22: =IF(tbRegras[[#This Row],[Código]]="","",IFERROR(INDEX(tbCategorias[Subcategoria],MATCH(tbRegras[[#This Row],[Código]],tbCategorias[Código],0)),"CÓDIGO INVÁLIDO")) -> Supermercado
A23: 22 | B23: Saúde e Cuidados | C23: Emergência Médica | D23: Não | E23: =tbCategorias[[#This Row],[Código]]&" - "&tbCategorias[[#This Row],[Subcategoria]] -> 22 - Emergência Médica | I23: ACOUGUE | J23: 11 | K23: =IF(tbRegras[[#This Row],[Código]]="","",IFERROR(INDEX(tbCategorias[Subcategoria],MATCH(tbRegras[[#This Row],[Código]],tbCategorias[Código],0)),"CÓDIGO INVÁLIDO")) -> Supermercado
A24: 23 | B24: Saúde e Cuidados | C24: Emergência Dentista | D24: Não | E24: =tbCategorias[[#This Row],[Código]]&" - "&tbCategorias[[#This Row],[Subcategoria]] -> 23 - Emergência Dentista | I24: PADARIA | J24: 13 | K24: =IF(tbRegras[[#This Row],[Código]]="","",IFERROR(INDEX(tbCategorias[Subcategoria],MATCH(tbRegras[[#This Row],[Código]],tbCategorias[Código],0)),"CÓDIGO INVÁLIDO")) -> Café / Almoço
A25: 24 | B25: Saúde e Cuidados | C25: Cosméticos | D25: Não | E25: =tbCategorias[[#This Row],[Código]]&" - "&tbCategorias[[#This Row],[Subcategoria]] -> 24 - Cosméticos | I25: LANCHONETE | J25: 13 | K25: =IF(tbRegras[[#This Row],[Código]]="","",IFERROR(INDEX(tbCategorias[Subcategoria],MATCH(tbRegras[[#This Row],[Código]],tbCategorias[Código],0)),"CÓDIGO INVÁLIDO")) -> Café / Almoço
A26: 25 | B26: Saúde e Cuidados | C26: Dentista | D26: Não | E26: =tbCategorias[[#This Row],[Código]]&" - "&tbCategorias[[#This Row],[Subcategoria]] -> 25 - Dentista | I26: RESTAURANTE | J26: 12 | K26: =IF(tbRegras[[#This Row],[Código]]="","",IFERROR(INDEX(tbCategorias[Subcategoria],MATCH(tbRegras[[#This Row],[Código]],tbCategorias[Código],0)),"CÓDIGO INVÁLIDO")) -> Restaurante
A27: 26 | B27: Saúde e Cuidados | C27: Exames Médicos | D27: Não | E27: =tbCategorias[[#This Row],[Código]]&" - "&tbCategorias[[#This Row],[Subcategoria]] -> 26 - Exames Médicos | I27: DROGA | J27: 27 | K27: =IF(tbRegras[[#This Row],[Código]]="","",IFERROR(INDEX(tbCategorias[Subcategoria],MATCH(tbRegras[[#This Row],[Código]],tbCategorias[Código],0)),"CÓDIGO INVÁLIDO")) -> Farmácia
A28: 27 | B28: Saúde e Cuidados | C28: Farmácia | D28: Não | E28: =tbCategorias[[#This Row],[Código]]&" - "&tbCategorias[[#This Row],[Subcategoria]] -> 27 - Farmácia | I28: FARMACIA | J28: 27 | K28: =IF(tbRegras[[#This Row],[Código]]="","",IFERROR(INDEX(tbCategorias[Subcategoria],MATCH(tbRegras[[#This Row],[Código]],tbCategorias[Código],0)),"CÓDIGO INVÁLIDO")) -> Farmácia
... A53: 64 | B53: Lazer | C53: Outros Lazer | D53: Não | E53: =tbCategorias[[#This Row],[Código]]&" - "&tbCategorias[[#This Row],[Subcategoria]] -> 64 - Outros Lazer | I53: ZARA | J53: 31 | K53: =IF(tbRegras[[#This Row],[Código]]="","",IFERROR(INDEX(tbCategorias[Subcategoria],MATCH(tbRegras[[#This Row],[Código]],tbCategorias[Código],0)),"CÓDIGO INVÁLIDO")) -> Roupas
A54: 70 | B54: Casa (Artigos) | C54: Cama | D54: Não | E54: =tbCategorias[[#This Row],[Código]]&" - "&tbCategorias[[#This Row],[Subcategoria]] -> 70 - Cama
A55: 71 | B55: Casa (Artigos) | C55: Consertos Futuros | D55: Não | E55: =tbCategorias[[#This Row],[Código]]&" - "&tbCategorias[[#This Row],[Subcategoria]] -> 71 - Consertos Futuros
A56: 72 | B56: Casa (Artigos) | C56: Geladeira | D56: Não | E56: =tbCategorias[[#This Row],[Código]]&" - "&tbCategorias[[#This Row],[Subcategoria]] -> 72 - Geladeira
A57: 73 | B57: Casa (Artigos) | C57: Lava e Seca | D57: Não | E57: =tbCategorias[[#This Row],[Código]]&" - "&tbCategorias[[#This Row],[Subcategoria]] -> 73 - Lava e Seca
A58: 74 | B58: Casa (Artigos) | C58: Lava-louças | D58: Não | E58: =tbCategorias[[#This Row],[Código]]&" - "&tbCategorias[[#This Row],[Subcategoria]] -> 74 - Lava-louças
A59: 75 | B59: Casa (Artigos) | C59: Utensílios e Decoração | D59: Não | E59: =tbCategorias[[#This Row],[Código]]&" - "&tbCategorias[[#This Row],[Subcategoria]] -> 75 - Utensílios e Decoração
A60: 76 | B60: Casa (Artigos) | C60: Outros Artigos | D60: Não | E60: =tbCategorias[[#This Row],[Código]]&" - "&tbCategorias[[#This Row],[Subcategoria]] -> 76 - Outros Artigos
A61: 80 | B61: Outros | C61: Presentes | D61: Não | E61: =tbCategorias[[#This Row],[Código]]&" - "&tbCategorias[[#This Row],[Subcategoria]] -> 80 - Presentes
A62: 81 | B62: Outros | C62: Doações | D62: Não | E62: =tbCategorias[[#This Row],[Código]]&" - "&tbCategorias[[#This Row],[Subcategoria]] -> 81 - Doações
A63: 82 | B63: Outros | C63: Ensaio | D63: Não | E63: =tbCategorias[[#This Row],[Código]]&" - "&tbCategorias[[#This Row],[Subcategoria]] -> 82 - Ensaio
A64: 83 | B64: Outros | C64: Outros | D64: Não | E64: =tbCategorias[[#This Row],[Código]]&" - "&tbCategorias[[#This Row],[Subcategoria]] -> 83 - Outros
A65: 4 | B65: Cartões e Dívidas | C65: Cartão Jhenismara | D65: Sim | E65: =tbCategorias[[#This Row],[Código]]&" - "&tbCategorias[[#This Row],[Subcategoria]] -> 4 - Cartão Jhenismara
... A77: 37 | B77: Investimentos | C77: Ações Alto Risco | D77: Não | E77: =tbCategorias[[#This Row],[Código]]&" - "&tbCategorias[[#This Row],[Subcategoria]] -> 37 - Ações Alto Risco
