Workbook
Name Receita: #REF!

Sheet JAN
A1: 4 | B1: Lançamento de Compras e Gastos Casa
I3: Previsto | K3: Real | N3: Diferença
H4: Renda 1 | I4: =2398+K66 -> 7488 | J4: 1940 | K4: =1940+J66 -> 2230 | N4: =I4-K4 -> 5258
H5: Renda 2 | I5: =2500+Q67 -> 2500 | J5: 2500 | K5: 2500 | N5: =I5-J5 -> 0
B6: Despesas Mensais | H6: Renda Total | I6: =+I4+I5 -> 9988 | K6: =+K4+K5 -> 4730 | N6: =+I6-K6 -> 5258
H7: Despesas | I7: =+SUM(I22,O24,I29,O34,I38,O42,I51,O52,I57,O59,I66,O67,) -> 19252.3 | K7: =+SUM(J22,J29,J38,J51,J57,J66,P67,P59,P52,P42,P34,P24,) -> 3651 | N7: =+I7-K7 -> 15601.3
B8: Data | C8: Despesa | D8: Valor | E8: Área | H8: Saldo | I8: =+I6-I7 -> -9264.3 | K8: =+K6-K7 -> 1079 | N8: =I8-K8 -> -10343.3
D9: =SUM(D10:D114) -> 0
B10: 45658
B11: 45659 | H11: MORADIA | I11: Previsto | J11: Real | K11: Diferença | N11: TRANSPORTE | O11: Previsto | P11: Real | Q11: Diferença
B12: 45660 | G12: 1 | H12: Caixa de Emergência | I12: 150 | J12: =SUMIF(E$10:E$146,"1",D$10:D$146) -> 0 | K12: =+I12-J12 -> 150 | M12: 40 | N12: Uber 99 | O12: 58 | P12: 45 | Q12: =+O12-P12 -> 13
B13: 45661 | G13: 2 | H13: Inevitavelmento fixo | I13: =J66 -> 290 | J13: =SUMIF(E$10:E$146,"2",D$10:D$146) -> 0 | K13: =+I13-J13 -> 290 | M13: 41 | N13: Uber | O13: 68 | P13: =SUMIF(E$10:E$146,"41",D$10:D$146) -> 0 | Q13: =+O13-P13 -> 68
B14: 45662 | G14: 3 | H14: Das Jhenis | I14: 250 | J14: =SUMIF(E$10:E$146,"3",D$10:D$146) -> 0 | K14: =+I14-J14 -> 250 | M14: 42 | N14: Transporte Público | O14: 440 | P14: 0 | Q14: =+O14-P14 -> 440
B15: 45663 | G15: 4 | H15: Cartao Jhenismara | I15: 1200 | J15: 1400 | K15: =+I15-J15 -> -200 | M15: 43 | N15: Transporte Trabalho J | O15: 240 | P15: 143 | Q15: =+O15-P15 -> 97
B16: 45664 | G16: 5 | H16: Emergência Casa | I16: 120 | J16: =SUMIF(E$10:E$146,"5",D$10:D$146) -> 0 | K16: =+I16-J16 -> 120 | M16: 44 | N16: Transporte Trabalho M | O16: 110 | P16: 240 | Q16: =+O16-P16 -> -130
B17: 45665 | G17: 6 | H17: Energia | I17: 150 | J17: 150 | K17: =+I17-J17 -> 0 | M17: 45 | N17: Caixa Carro J | O17: 0 | P17: =SUMIF(E$10:E$146,"45",D$10:D$146) -> 0 | Q17: =+O17-P17 -> 0
B18: 45666 | G18: 7 | H18: Água | I18: 77 | J18: 77 | K18: =+I18-J18 -> 0 | M18: 46 | N18: Caixa Carro M | O18: 0 | P18: =SUMIF(E$10:E$146,"46",D$10:D$146) -> 0 | Q18: =+O18-P18 -> 0
B19: 45667 | G19: 8 | H19: Gás | I19: 55 | J19: 55 | K19: =+I19-J19 -> 0 | M19: 47 | N19: Contas Extras | O19: 0 | P19: =SUMIF(E$10:E$146,"47",D$10:D$146) -> 0 | Q19: =+O19-P19 -> 0
B20: 45668 | G20: 9 | H20: Cartao (Matheus) | I20: 175 | J20: 175 | K20: =+I20-J20 -> 0 | M20: 48 | O20: 0 | P20: =SUMIF(E$10:E$146,"48",D$10:D$146) -> 0 | Q20: =+O20-P20 -> 0
B21: 45669 | G21: 10 | H21: Outrs Dispesas | I21: 0 | J21: =SUMIF(E$10:E$146,"10",D$10:D$146) -> 0 | K21: =+I21-J21 -> 0 | M21: 49 | O21: 0 | P21: 0 | Q21: =+O21-P21 -> 0
B22: 45670 | H22: TOTAL | I22: =SUM(I12:I21) -> 2467 | J22: =SUM(J12:J21) -> 1857 | K22: =+I22-J22 -> 610 | M22: 50 | O22: 0 | P22: 0 | Q22: =+O22-P22 -> 0
B23: 45671 | M23: 51 | O23: 0 | P23: =SUMIF(E$10:E$146,"51",D$10:D$146) -> 0 | Q23: =+O23-P23 -> 0
B24: 45672 | H24: ALIMENTAÇÃO | I24: Previsto | J24: Real | K24: Diferença | N24: TOTAL | O24: =SUM(O12:O23) -> 916 | P24: =SUM(P12:P23) -> 428 | Q24: =+O24-P24 -> 488
B25: 45673 | G25: 11 | H25: Supermercado | I25: 450 | J25: 450 | K25: =+I25-J25 -> 0
B26: 45674 | G26: 12 | H26: Restaurante | I26: 140 | J26: 140 | K26: =+I26-J26 -> 0 | N26: EDUCAÇÃO | O26: Previsto | P26: Real | Q26: Diferença
B27: 45675 | G27: 13 | H27: Café \ Almoço | I27: 100 | J27: 250 | K27: =+I27-J27 -> -150 | M27: 52 | N27: Mensalidades | O27: 0 | P27: =SUMIF(E$10:E$146,"52",D$10:D$146) -> 0 | Q27: =+O27-P27 -> 0
B28: 45676 | G28: 14 | H28: Pedidos IFood | I28: 140 | J28: =SUMIF(E$10:E$146,"14",D$10:D$146) -> 0 | K28: =+I28-J28 -> 140 | M28: 53 | N28: Idiomas | O28: 0 | P28: =SUMIF(E$10:E$146,"53",D$10:D$146) -> 0 | Q28: =+O28-P28 -> 0
B29: 45677 | H29: TOTAL | I29: =SUM(I25:I28) -> 830 | J29: =SUM(J25:J28) -> 840 | K29: =+I29-J29 -> -10 | M29: 54 | N29: CNH [Matheus] | O29: 0 | P29: =SUMIF(E$10:E$146,"54",D$10:D$146) -> 0 | Q29: =+O29-P29 -> 0
B30: 45678 | M30: 55 | N30: Cursos | O30: 140 | P30: =SUMIF(E$10:E$146,"55",D$10:D$146) -> 0 | Q30: =+O30-P30 -> 140
B31: 45679 | H31: COMUNICAÇÃO | I31: Previsto | J31: Real | K31: Diferença | M31: 56 | N31: Livros | O31: 0 | P31: =SUMIF(E$10:E$146,"56",D$10:D$146) -> 0 | Q31: =+O31-P31 -> 0
B32: 45680 | G32: 15 | H32: Celular | I32: 45 | J32: 45 | K32: =+I32-J32 -> 0 | M32: 57 | N32: Faculdade [Jhenis] | O32: 0 | P32: =SUMIF(E$10:E$146,"57",D$10:D$146) -> 0 | Q32: =+O32-P32 -> 0
B33: 45681 | G33: 16 | H33: Internet | I33: 89 | J33: 89 | K33: =+I33-J33 -> 0 | M33: 58 | N33: Outros Educação | O33: 0 | P33: =SUMIF(E$10:E$146,"58",D$10:D$146) -> 0 | Q33: =+O33-P33 -> 0
B34: 45682 | G34: 17 | H34: Streaming | I34: 24 | J34: 24 | K34: =+I34-J34 -> 0 | N34: TOTAL | O34: =SUM(O27:O33) -> 140 | P34: =SUM(P27:P33) -> 0 | Q34: =+O34-P34 -> 140
B35: 45683 | G35: 18 | H35: Netflix | I35: 21.9 | J35: 22 | K35: =+I35-J35 -> -0.1
B36: 45684 | G36: 19 | H36: Amazon | I36: 10.9 | J36: 11 | K36: =+I36-J36 -> -0.1 | N36: LAZER | O36: Previsto | P36: Real | Q36: Diferença
B37: 45685 | G37: 20 | H37: Max Plus | I37: 34.5 | J37: 45 | K37: =+I37-J37 -> -10.5 | M37: 60 | N37: Cinema | O37: 450 | P37: =SUMIF(E$10:E$146,"60",D$10:D$146) -> 0 | Q37: =+O37-P37 -> 450
B38: 45686 | H38: TOTAL | I38: =SUM(I32:I37) -> 225.3 | J38: =SUM(J32:J37) -> 236 | K38: =+I38-J38 -> -10.7 | M38: 61 | N38: Esportes | O38: 0 | P38: =SUMIF(E$10:E$146,"61",D$10:D$146) -> 0 | Q38: =+O38-P38 -> 0
B39: 45687 | M39: 62 | N39: Shows [Consertos] | O39: 120 | P39: =SUMIF(E$10:E$146,"62",D$10:D$146) -> 0 | Q39: =+O39-P39 -> 120
B40: 45688 | H40: SAÚDE E CUIDADOS | I40: Previsto | J40: Real | K40: Diferença | M40: 63 | N40: Viagens [Férias] | O40: 148 | P40: =SUMIF(E$10:E$146,"63",D$10:D$146) -> 0 | Q40: =+O40-P40 -> 148
G41: 21 | H41: Academia | I41: 120 | J41: =SUMIF(E$10:E$146,"21",D$10:D$146) -> 0 | K41: =+I41-J41 -> 120 | M41: 64 | N41: Outros Lazer | O41: 60 | P41: =SUMIF(E$10:E$146,"64",D$10:D$146) -> 0 | Q41: =+O41-P41 -> 60
...

Sheet FEV
B1: Lançamento de Compras e Gastos Casa
I3: Previsto | K3: Real | N3: Diferença
H4: Renda 1 | I4: =2398+K66 -> 2398 | J4: 1940 | K4: =1940+J66 -> 1940 | N4: =I4-K4 -> 458
H5: Renda 2 | I5: =2500+Q67 -> 2500 | J5: 2500 | K5: 2500 | N5: =I5-J5 -> 0
B6: Despesas Mensais | H6: Renda Total | I6: =+I4+I5 -> 4898 | K6: =+K4+K5 -> 4440 | N6: =+I6-K6 -> 458
H7: Despesas | I7: =+SUM(I22,O24,I29,O34,I38,O42,I51,O52,I57,O59,I66,O67,) -> 7213.3 | K7: =+SUM(J22,J29,J38,J51,J57,J66,P67,P59,P52,P42,P34,P24,) -> 3361 | N7: =+I7-K7 -> 3852.3
B8: Data | C8: Despesa | D8: Valor | E8: Área | H8: Saldo | I8: =+I6-I7 -> -2315.3 | K8: =+K6-K7 -> 1079 | N8: =I8-K8 -> -3394.3
D9: =SUM(D10:D112) -> 0
B10: 45689
B11: 45690 | H11: MORADIA | I11: Previsto | J11: Real | K11: Diferença | N11: TRANSPORTE | O11: Previsto | P11: Real | Q11: Diferença
B12: 45691 | G12: 1 | H12: Caixa de Emergência | I12: 150 | J12: =SUMIF(E$10:E$144,"1",D$10:D$144) -> 0 | K12: =+I12-J12 -> 150 | M12: 40 | N12: Uber 99 | O12: 58 | P12: 45 | Q12: =+O12-P12 -> 13
B13: 45692 | G13: 2 | H13: Inevitavelmento fixo | I13: 1200 | J13: =SUMIF(E$10:E$144,"2",D$10:D$144) -> 0 | K13: =+I13-J13 -> 1200 | M13: 41 | N13: Uber | O13: 68 | P13: =SUMIF(E$10:E$144,"41",D$10:D$144) -> 0 | Q13: =+O13-P13 -> 68
B14: 45693 | G14: 3 | H14: Das Jhenis | I14: 250 | J14: =SUMIF(E$10:E$144,"3",D$10:D$144) -> 0 | K14: =+I14-J14 -> 250 | M14: 42 | N14: Transporte Público | O14: 440 | P14: 0 | Q14: =+O14-P14 -> 440
B15: 45694 | G15: 4 | H15: Cartao Jhenismara | I15: 1200 | J15: 1400 | K15: =+I15-J15 -> -200 | M15: 43 | N15: Transporte Trabalho J | O15: 240 | P15: 143 | Q15: =+O15-P15 -> 97
B16: 45695 | G16: 5 | H16: Emergência Casa | I16: 120 | J16: =SUMIF(E$10:E$144,"5",D$10:D$144) -> 0 | K16: =+I16-J16 -> 120 | M16: 44 | N16: Transporte Trabalho M | O16: 110 | P16: 240 | Q16: =+O16-P16 -> -130
B17: 45696 | G17: 6 | H17: Energia | I17: 150 | J17: 150 | K17: =+I17-J17 -> 0 | M17: 45 | N17: Caixa Carro J | O17: 0 | P17: =SUMIF(E$10:E$144,"45",D$10:D$144) -> 0 | Q17: =+O17-P17 -> 0
B18: 45697 | G18: 7 | H18: Água | I18: 77 | J18: 77 | K18: =+I18-J18 -> 0 | M18: 46 | N18: Caixa Carro M | O18: 0 | P18: =SUMIF(E$10:E$144,"46",D$10:D$144) -> 0 | Q18: =+O18-P18 -> 0
B19: 45698 | G19: 8 | H19: Gás | I19: 55 | J19: 55 | K19: =+I19-J19 -> 0 | M19: 47 | O19: 0 | P19: =SUMIF(E$10:E$144,"47",D$10:D$144) -> 0 | Q19: =+O19-P19 -> 0
B20: 45699 | G20: 9 | H20: Cartao (Matheus) | I20: 175 | J20: 175 | K20: =+I20-J20 -> 0 | M20: 48 | O20: 0 | P20: =SUMIF(E$10:E$144,"48",D$10:D$144) -> 0 | Q20: =+O20-P20 -> 0
B21: 45700 | G21: 10 | H21: Outrs Dispesas | J21: =SUMIF(E$10:E$144,"10",D$10:D$144) -> 0 | K21: =+I21-J21 -> 0 | M21: 49 | O21: 0 | P21: 0 | Q21: =+O21-P21 -> 0
B22: 45701 | H22: TOTAL | I22: =SUM(I12:I21) -> 3377 | J22: =SUM(J12:J21) -> 1857 | K22: =+I22-J22 -> 1520 | M22: 50 | O22: 0 | P22: 0 | Q22: =+O22-P22 -> 0
B23: 45702 | M23: 51 | N23: Outros Transporte | O23: 0 | P23: =SUMIF(E$10:E$144,"51",D$10:D$144) -> 0 | Q23: =+O23-P23 -> 0
B24: 45703 | H24: ALIMENTAÇÃO | I24: Previsto | J24: Real | K24: Diferença | N24: TOTAL | O24: =SUM(O12:O23) -> 916 | P24: =SUM(P12:P23) -> 428 | Q24: =+O24-P24 -> 488
B25: 45704 | G25: 11 | H25: Supermercado | I25: 450 | J25: 450 | K25: =+I25-J25 -> 0
B26: 45705 | G26: 12 | H26: Restaurante | I26: 140 | J26: 140 | K26: =+I26-J26 -> 0 | N26: EDUCAÇÃO | O26: Previsto | P26: Real | Q26: Diferença
B27: 45706 | G27: 13 | H27: Café \ Almoço | I27: 100 | J27: 250 | K27: =+I27-J27 -> -150 | M27: 52 | N27: Mensalidades | O27: 0 | P27: =SUMIF(E$10:E$144,"52",D$10:D$144) -> 0 | Q27: =+O27-P27 -> 0
B28: 45707 | G28: 14 | H28: Pedidos IFood | I28: 140 | J28: =SUMIF(E$10:E$144,"14",D$10:D$144) -> 0 | K28: =+I28-J28 -> 140 | M28: 53 | N28: Idiomas | O28: 0 | P28: =SUMIF(E$10:E$144,"53",D$10:D$144) -> 0 | Q28: =+O28-P28 -> 0
B29: 45708 | H29: TOTAL | I29: =SUM(I25:I28) -> 830 | J29: =SUM(J25:J28) -> 840 | K29: =+I29-J29 -> -10 | M29: 54 | N29: CNH [Matheus] | O29: 0 | P29: =SUMIF(E$10:E$144,"54",D$10:D$144) -> 0 | Q29: =+O29-P29 -> 0
B30: 45709 | M30: 55 | N30: Cursos | O30: 140 | P30: =SUMIF(E$10:E$144,"55",D$10:D$144) -> 0 | Q30: =+O30-P30 -> 140
B31: 45710 | H31: COMUNICAÇÃO | I31: Previsto | J31: Real | K31: Diferença | M31: 56 | N31: Livros | O31: 0 | P31: =SUMIF(E$10:E$144,"56",D$10:D$144) -> 0 | Q31: =+O31-P31 -> 0
B32: 45711 | G32: 15 | H32: Celular | I32: 45 | J32: 45 | K32: =+I32-J32 -> 0 | M32: 57 | N32: Faculdade [Jhenis] | O32: 0 | P32: =SUMIF(E$10:E$144,"57",D$10:D$144) -> 0 | Q32: =+O32-P32 -> 0
B33: 45712 | G33: 16 | H33: Internet | I33: 89 | J33: 89 | K33: =+I33-J33 -> 0 | M33: 58 | N33: Outros Educação | O33: 0 | P33: =SUMIF(E$10:E$144,"58",D$10:D$144) -> 0 | Q33: =+O33-P33 -> 0
B34: 45713 | G34: 17 | H34: Streaming | I34: 24 | J34: 24 | K34: =+I34-J34 -> 0 | N34: TOTAL | O34: =SUM(O27:O33) -> 140 | P34: =SUM(P27:P33) -> 0 | Q34: =+O34-P34 -> 140
B35: 45714 | G35: 18 | H35: Netflix | I35: 21.9 | J35: 22 | K35: =+I35-J35 -> -0.1
B36: 45715 | G36: 19 | H36: Amazon | I36: 10.9 | J36: 11 | K36: =+I36-J36 -> -0.1 | N36: LAZER | O36: Previsto | P36: Real | Q36: Diferença
B37: 45716 | G37: 20 | H37: Max Plus | I37: 34.5 | J37: 45 | K37: =+I37-J37 -> -10.5 | M37: 60 | N37: Cinema | O37: 450 | P37: =SUMIF(E$10:E$144,"60",D$10:D$144) -> 0 | Q37: =+O37-P37 -> 450
H38: TOTAL | I38: =SUM(I32:I37) -> 225.3 | J38: =SUM(J32:J37) -> 236 | K38: =+I38-J38 -> -10.7 | M38: 61 | N38: Esportes | O38: 0 | P38: =SUMIF(E$10:E$144,"61",D$10:D$144) -> 0 | Q38: =+O38-P38 -> 0
M39: 62 | N39: Shows [Consertos] | O39: 120 | P39: =SUMIF(E$10:E$144,"62",D$10:D$144) -> 0 | Q39: =+O39-P39 -> 120
H40: SAÚDE E CUIDADOS | I40: Previsto | J40: Real | K40: Diferença | M40: 63 | N40: Viagens [Férias] | O40: 148 | P40: =SUMIF(E$10:E$144,"63",D$10:D$144) -> 0 | Q40: =+O40-P40 -> 148
G41: 21 | H41: Academia | I41: 120 | J41: =SUMIF(E$10:E$144,"21",D$10:D$144) -> 0 | K41: =+I41-J41 -> 120 | M41: 64 | N41: Outros Lazer | O41: 60 | P41: =SUMIF(E$10:E$144,"64",D$10:D$144) -> 0 | Q41: =+O41-P41 -> 60
...

Sheet MAR
B1: Lançamento de Compras e Gastos Casa Organizada
I3: Previsto | K3: Real | N3: Diferença
H4: Renda 1 | I4: 2398 | J4: 1940 | K4: 1940 | N4: =I4-K4 -> 458
H5: Renda 2 | I5: 2500 | J5: 2500 | K5: 2500 | N5: =I5-J5 -> 0
B6: Despesas Mensais | H6: Renda Total | I6: =+I4+I5 -> 4898 | K6: =+K4+K5 -> 4440 | N6: =+I6-K6 -> 458
H7: Despesas | I7: =+SUM(I22,O24,I29,O34,I38,O42,I51,O52,I57,O59,I64,O65,) -> 12013.3 | K7: =+SUM(J22,J29,J38,J51,J57,J64,P65,P59,P52,P42,P34,P24,) -> 3361 | N7: =+I7-K7 -> 8652.3
B8: Data | C8: Despesa | D8: Valor | E8: Área | H8: Saldo | I8: =+I6-I7 -> -7115.3 | K8: =+K6-K7 -> 1079 | N8: =I8-K8 -> -8194.3
D9: =SUM(D10:D112) -> 0
B10: 45717
B11: 45718 | H11: MORADIA | I11: Previsto | J11: Real | K11: Diferença | N11: TRANSPORTE | O11: Previsto | P11: Real | Q11: Diferença
B12: 45719 | G12: 1 | H12: Caixa de Emergência | I12: 150 | J12: =SUMIF(E$10:E$144,"1",D$10:D$144) -> 0 | K12: =+I12-J12 -> 150 | M12: 40 | N12: Uber 99 | O12: 58 | P12: 45 | Q12: =+O12-P12 -> 13
B13: 45720 | G13: 2 | H13: Inevitavelmento fixo | I13: 1200 | J13: =SUMIF(E$10:E$144,"2",D$10:D$144) -> 0 | K13: =+I13-J13 -> 1200 | M13: 41 | N13: Uber | O13: 68 | P13: =SUMIF(E$10:E$144,"41",D$10:D$144) -> 0 | Q13: =+O13-P13 -> 68
B14: 45721 | G14: 3 | H14: Das Jhenis | I14: 250 | J14: =SUMIF(E$10:E$144,"3",D$10:D$144) -> 0 | K14: =+I14-J14 -> 250 | M14: 42 | N14: Transporte Público | O14: 440 | P14: 0 | Q14: =+O14-P14 -> 440
B15: 45722 | G15: 4 | H15: Cartao Jhenismara | I15: 1200 | J15: 1400 | K15: =+I15-J15 -> -200 | M15: 43 | N15: Transporte Trabalho J | O15: 240 | P15: 143 | Q15: =+O15-P15 -> 97
B16: 45723 | G16: 5 | H16: Emergência Casa | I16: 120 | J16: =SUMIF(E$10:E$144,"5",D$10:D$144) -> 0 | K16: =+I16-J16 -> 120 | M16: 44 | N16: Transporte Trabalho M | O16: 110 | P16: 240 | Q16: =+O16-P16 -> -130
B17: 45724 | G17: 6 | H17: Energia | I17: 150 | J17: 150 | K17: =+I17-J17 -> 0 | M17: 45 | N17: Caixa Carro J | O17: 0 | P17: =SUMIF(E$10:E$144,"45",D$10:D$144) -> 0 | Q17: =+O17-P17 -> 0
B18: 45725 | G18: 7 | H18: Água | I18: 77 | J18: 77 | K18: =+I18-J18 -> 0 | M18: 46 | N18: Caixa Carro M | O18: 0 | P18: =SUMIF(E$10:E$144,"46",D$10:D$144) -> 0 | Q18: =+O18-P18 -> 0
B19: 45726 | G19: 8 | H19: Gás | I19: 55 | J19: 55 | K19: =+I19-J19 -> 0 | M19: 47 | O19: 0 | P19: =SUMIF(E$10:E$144,"47",D$10:D$144) -> 0 | Q19: =+O19-P19 -> 0
B20: 45727 | G20: 9 | H20: Cartao (Matheus) | I20: 175 | J20: 175 | K20: =+I20-J20 -> 0 | M20: 48 | O20: 0 | P20: =SUMIF(E$10:E$144,"48",D$10:D$144) -> 0 | Q20: =+O20-P20 -> 0
B21: 45728 | G21: 10 | H21: Outrs Dispesas | J21: =SUMIF(E$10:E$144,"10",D$10:D$144) -> 0 | K21: =+I21-J21 -> 0 | M21: 49 | O21: 0 | P21: 0 | Q21: =+O21-P21 -> 0
B22: 45729 | H22: TOTAL | I22: =SUM(I12:I21) -> 3377 | J22: =SUM(J12:J21) -> 1857 | K22: =+I22-J22 -> 1520 | M22: 50 | O22: 0 | P22: 0 | Q22: =+O22-P22 -> 0
B23: 45730 | M23: 51 | N23: Outros Transporte | O23: 0 | P23: =SUMIF(E$10:E$144,"51",D$10:D$144) -> 0 | Q23: =+O23-P23 -> 0
B24: 45731 | H24: ALIMENTAÇÃO | I24: Previsto | J24: Real | K24: Diferença | N24: TOTAL | O24: =SUM(O12:O23) -> 916 | P24: =SUM(P12:P23) -> 428 | Q24: =+O24-P24 -> 488
B25: 45732 | G25: 11 | H25: Supermercado | I25: 450 | J25: 450 | K25: =+I25-J25 -> 0
B26: 45733 | G26: 12 | H26: Restaurante | I26: 140 | J26: 140 | K26: =+I26-J26 -> 0 | N26: EDUCAÇÃO | O26: Previsto | P26: Real | Q26: Diferença
B27: 45734 | G27: 13 | H27: Café \ Almoço | I27: 100 | J27: 250 | K27: =+I27-J27 -> -150 | M27: 52 | N27: Mensalidades | O27: 0 | P27: =SUMIF(E$10:E$144,"52",D$10:D$144) -> 0 | Q27: =+O27-P27 -> 0
B28: 45735 | G28: 14 | H28: Pedidos IFood | I28: 140 | J28: =SUMIF(E$10:E$144,"14",D$10:D$144) -> 0 | K28: =+I28-J28 -> 140 | M28: 53 | N28: Idiomas | O28: 0 | P28: =SUMIF(E$10:E$144,"53",D$10:D$144) -> 0 | Q28: =+O28-P28 -> 0
B29: 45736 | H29: TOTAL | I29: =SUM(I25:I28) -> 830 | J29: =SUM(J25:J28) -> 840 | K29: =+I29-J29 -> -10 | M29: 54 | N29: CNH [Matheus] | O29: 0 | P29: =SUMIF(E$10:E$144,"54",D$10:D$144) -> 0 | Q29: =+O29-P29 -> 0
B30: 45737 | M30: 55 | N30: Cursos | O30: 140 | P30: =SUMIF(E$10:E$144,"55",D$10:D$144) -> 0 | Q30: =+O30-P30 -> 140
B31: 45738 | H31: COMUNICAÇÃO | I31: Previsto | J31: Real | K31: Diferença | M31: 56 | N31: Livros | O31: 0 | P31: =SUMIF(E$10:E$144,"56",D$10:D$144) -> 0 | Q31: =+O31-P31 -> 0
B32: 45739 | G32: 15 | H32: Celular | I32: 45 | J32: 45 | K32: =+I32-J32 -> 0 | M32: 57 | N32: Faculdade [Jhenis] | O32: 0 | P32: =SUMIF(E$10:E$144,"57",D$10:D$144) -> 0 | Q32: =+O32-P32 -> 0
B33: 45740 | G33: 16 | H33: Internet | I33: 89 | J33: 89 | K33: =+I33-J33 -> 0 | M33: 58 | N33: Outros Educação | O33: 0 | P33: =SUMIF(E$10:E$144,"58",D$10:D$144) -> 0 | Q33: =+O33-P33 -> 0
B34: 45741 | G34: 17 | H34: Streaming | I34: 24 | J34: 24 | K34: =+I34-J34 -> 0 | N34: TOTAL | O34: =SUM(O27:O33) -> 140 | P34: =SUM(P27:P33) -> 0 | Q34: =+O34-P34 -> 140
B35: 45742 | G35: 18 | H35: Netflix | I35: 21.9 | J35: 22 | K35: =+I35-J35 -> -0.1
B36: 45743 | G36: 19 | H36: Amazon | I36: 10.9 | J36: 11 | K36: =+I36-J36 -> -0.1 | N36: LAZER | O36: Previsto | P36: Real | Q36: Diferença
B37: 45744 | G37: 20 | H37: Max Plus | I37: 34.5 | J37: 45 | K37: =+I37-J37 -> -10.5 | M37: 60 | N37: Cinema | O37: 450 | P37: =SUMIF(E$10:E$144,"60",D$10:D$144) -> 0 | Q37: =+O37-P37 -> 450
B38: 45745 | H38: TOTAL | I38: =SUM(I32:I37) -> 225.3 | J38: =SUM(J32:J37) -> 236 | K38: =+I38-J38 -> -10.7 | M38: 61 | N38: Esportes | O38: 0 | P38: =SUMIF(E$10:E$144,"61",D$10:D$144) -> 0 | Q38: =+O38-P38 -> 0
B39: 45746 | M39: 62 | N39: Shows [Consertos] | O39: 120 | P39: =SUMIF(E$10:E$144,"62",D$10:D$144) -> 0 | Q39: =+O39-P39 -> 120
B40: 45747 | H40: SAÚDE E CUIDADOS | I40: Previsto | J40: Real | K40: Diferença | M40: 63 | N40: Viagens [Férias] | O40: 148 | P40: =SUMIF(E$10:E$144,"63",D$10:D$144) -> 0 | Q40: =+O40-P40 -> 148
G41: 21 | H41: Academia | I41: 120 | J41: =SUMIF(E$10:E$144,"21",D$10:D$144) -> 0 | K41: =+I41-J41 -> 120 | M41: 64 | N41: Outros Lazer | O41: 60 | P41: =SUMIF(E$10:E$144,"64",D$10:D$144) -> 0 | Q41: =+O41-P41 -> 60
...

Sheet ABR
B1: Lançamento de Compras e Gastos Casa Organizada
I3: Previsto | K3: Real | N3: Diferença
H4: Renda 1 | I4: 2398 | J4: 1940 | K4: 1940 | N4: =I4-K4 -> 458
H5: Renda 2 | I5: 2500 | J5: 2500 | K5: 2500 | N5: =I5-J5 -> 0
B6: Despesas Mensais | H6: Renda Total | I6: =+I4+I5 -> 4898 | K6: =+K4+K5 -> 4440 | N6: =+I6-K6 -> 458
H7: Despesas | I7: =+SUM(I22,O24,I29,O34,I38,O42,I51,O52,I57,O59,I64,O65,) -> 12013.3 | K7: =+SUM(J22,J29,J38,J51,J57,J64,P65,P59,P52,P42,P34,P24,) -> 3361 | N7: =+I7-K7 -> 8652.3
B8: Data | C8: Despesa | D8: Valor | E8: Área | H8: Saldo | I8: =+I6-I7 -> -7115.3 | K8: =+K6-K7 -> 1079 | N8: =I8-K8 -> -8194.3
D9: =SUM(D10:D112) -> 0
B10: 45748
B11: 45749 | H11: MORADIA | I11: Previsto | J11: Real | K11: Diferença | N11: TRANSPORTE | O11: Previsto | P11: Real | Q11: Diferença
B12: 45750 | G12: 1 | H12: Caixa de Emergência | I12: 150 | J12: =SUMIF(E$10:E$144,"1",D$10:D$144) -> 0 | K12: =+I12-J12 -> 150 | M12: 40 | N12: Uber 99 | O12: 58 | P12: 45 | Q12: =+O12-P12 -> 13
B13: 45751 | G13: 2 | H13: Inevitavelmento fixo | I13: 1200 | J13: =SUMIF(E$10:E$144,"2",D$10:D$144) -> 0 | K13: =+I13-J13 -> 1200 | M13: 41 | N13: Uber | O13: 68 | P13: =SUMIF(E$10:E$144,"41",D$10:D$144) -> 0 | Q13: =+O13-P13 -> 68
B14: 45752 | G14: 3 | H14: Das Jhenis | I14: 250 | J14: =SUMIF(E$10:E$144,"3",D$10:D$144) -> 0 | K14: =+I14-J14 -> 250 | M14: 42 | N14: Transporte Público | O14: 440 | P14: 0 | Q14: =+O14-P14 -> 440
B15: 45753 | G15: 4 | H15: Cartao Jhenismara | I15: 1200 | J15: 1400 | K15: =+I15-J15 -> -200 | M15: 43 | N15: Transporte Trabalho J | O15: 240 | P15: 143 | Q15: =+O15-P15 -> 97
B16: 45754 | G16: 5 | H16: Emergência Casa | I16: 120 | J16: =SUMIF(E$10:E$144,"5",D$10:D$144) -> 0 | K16: =+I16-J16 -> 120 | M16: 44 | N16: Transporte Trabalho M | O16: 110 | P16: 240 | Q16: =+O16-P16 -> -130
B17: 45755 | G17: 6 | H17: Energia | I17: 150 | J17: 150 | K17: =+I17-J17 -> 0 | M17: 45 | N17: Caixa Carro J | O17: 0 | P17: =SUMIF(E$10:E$144,"45",D$10:D$144) -> 0 | Q17: =+O17-P17 -> 0
B18: 45756 | G18: 7 | H18: Água | I18: 77 | J18: 77 | K18: =+I18-J18 -> 0 | M18: 46 | N18: Caixa Carro M | O18: 0 | P18: =SUMIF(E$10:E$144,"46",D$10:D$144) -> 0 | Q18: =+O18-P18 -> 0
B19: 45757 | G19: 8 | H19: Gás | I19: 55 | J19: 55 | K19: =+I19-J19 -> 0 | M19: 47 | O19: 0 | P19: =SUMIF(E$10:E$144,"47",D$10:D$144) -> 0 | Q19: =+O19-P19 -> 0
B20: 45758 | G20: 9 | H20: Cartao (Matheus) | I20: 175 | J20: 175 | K20: =+I20-J20 -> 0 | M20: 48 | O20: 0 | P20: =SUMIF(E$10:E$144,"48",D$10:D$144) -> 0 | Q20: =+O20-P20 -> 0
B21: 45759 | G21: 10 | H21: Outrs Dispesas | J21: =SUMIF(E$10:E$144,"10",D$10:D$144) -> 0 | K21: =+I21-J21 -> 0 | M21: 49 | O21: 0 | P21: 0 | Q21: =+O21-P21 -> 0
B22: 45760 | H22: TOTAL | I22: =SUM(I12:I21) -> 3377 | J22: =SUM(J12:J21) -> 1857 | K22: =+I22-J22 -> 1520 | M22: 50 | O22: 0 | P22: 0 | Q22: =+O22-P22 -> 0
B23: 45761 | M23: 51 | N23: Outros Transporte | O23: 0 | P23: =SUMIF(E$10:E$144,"51",D$10:D$144) -> 0 | Q23: =+O23-P23 -> 0
B24: 45762 | H24: ALIMENTAÇÃO | I24: Previsto | J24: Real | K24: Diferença | N24: TOTAL | O24: =SUM(O12:O23) -> 916 | P24: =SUM(P12:P23) -> 428 | Q24: =+O24-P24 -> 488
B25: 45763 | G25: 11 | H25: Supermercado | I25: 450 | J25: 450 | K25: =+I25-J25 -> 0
B26: 45764 | G26: 12 | H26: Restaurante | I26: 140 | J26: 140 | K26: =+I26-J26 -> 0 | N26: EDUCAÇÃO | O26: Previsto | P26: Real | Q26: Diferença
B27: 45765 | G27: 13 | H27: Café \ Almoço | I27: 100 | J27: 250 | K27: =+I27-J27 -> -150 | M27: 52 | N27: Mensalidades | O27: 0 | P27: =SUMIF(E$10:E$144,"52",D$10:D$144) -> 0 | Q27: =+O27-P27 -> 0
B28: 45766 | G28: 14 | H28: Pedidos IFood | I28: 140 | J28: =SUMIF(E$10:E$144,"14",D$10:D$144) -> 0 | K28: =+I28-J28 -> 140 | M28: 53 | N28: Idiomas | O28: 0 | P28: =SUMIF(E$10:E$144,"53",D$10:D$144) -> 0 | Q28: =+O28-P28 -> 0
B29: 45767 | H29: TOTAL | I29: =SUM(I25:I28) -> 830 | J29: =SUM(J25:J28) -> 840 | K29: =+I29-J29 -> -10 | M29: 54 | N29: CNH [Matheus] | O29: 0 | P29: =SUMIF(E$10:E$144,"54",D$10:D$144) -> 0 | Q29: =+O29-P29 -> 0
B30: 45768 | M30: 55 | N30: Cursos | O30: 140 | P30: =SUMIF(E$10:E$144,"55",D$10:D$144) -> 0 | Q30: =+O30-P30 -> 140
B31: 45769 | H31: COMUNICAÇÃO | I31: Previsto | J31: Real | K31: Diferença | M31: 56 | N31: Livros | O31: 0 | P31: =SUMIF(E$10:E$144,"56",D$10:D$144) -> 0 | Q31: =+O31-P31 -> 0
B32: 45770 | G32: 15 | H32: Celular | I32: 45 | J32: 45 | K32: =+I32-J32 -> 0 | M32: 57 | N32: Faculdade [Jhenis] | O32: 0 | P32: =SUMIF(E$10:E$144,"57",D$10:D$144) -> 0 | Q32: =+O32-P32 -> 0
B33: 45771 | G33: 16 | H33: Internet | I33: 89 | J33: 89 | K33: =+I33-J33 -> 0 | M33: 58 | N33: Outros Educação | O33: 0 | P33: =SUMIF(E$10:E$144,"58",D$10:D$144) -> 0 | Q33: =+O33-P33 -> 0
B34: 45772 | G34: 17 | H34: Streaming | I34: 24 | J34: 24 | K34: =+I34-J34 -> 0 | N34: TOTAL | O34: =SUM(O27:O33) -> 140 | P34: =SUM(P27:P33) -> 0 | Q34: =+O34-P34 -> 140
B35: 45773 | G35: 18 | H35: Netflix | I35: 21.9 | J35: 22 | K35: =+I35-J35 -> -0.1
B36: 45774 | G36: 19 | H36: Amazon | I36: 10.9 | J36: 11 | K36: =+I36-J36 -> -0.1 | N36: LAZER | O36: Previsto | P36: Real | Q36: Diferença
B37: 45775 | G37: 20 | H37: Max Plus | I37: 34.5 | J37: 45 | K37: =+I37-J37 -> -10.5 | M37: 60 | N37: Cinema | O37: 450 | P37: =SUMIF(E$10:E$144,"60",D$10:D$144) -> 0 | Q37: =+O37-P37 -> 450
B38: 45776 | H38: TOTAL | I38: =SUM(I32:I37) -> 225.3 | J38: =SUM(J32:J37) -> 236 | K38: =+I38-J38 -> -10.7 | M38: 61 | N38: Esportes | O38: 0 | P38: =SUMIF(E$10:E$144,"61",D$10:D$144) -> 0 | Q38: =+O38-P38 -> 0
B39: 45777 | M39: 62 | N39: Shows [Consertos] | O39: 120 | P39: =SUMIF(E$10:E$144,"62",D$10:D$144) -> 0 | Q39: =+O39-P39 -> 120
H40: SAÚDE E CUIDADOS | I40: Previsto | J40: Real | K40: Diferença | M40: 63 | N40: Viagens [Férias] | O40: 148 | P40: =SUMIF(E$10:E$144,"63",D$10:D$144) -> 0 | Q40: =+O40-P40 -> 148
G41: 21 | H41: Academia | I41: 120 | J41: =SUMIF(E$10:E$144,"21",D$10:D$144) -> 0 | K41: =+I41-J41 -> 120 | M41: 64 | N41: Outros Lazer | O41: 60 | P41: =SUMIF(E$10:E$144,"64",D$10:D$144) -> 0 | Q41: =+O41-P41 -> 60
...

Sheet MAI
A1: Lançamento de Compras e Gastos Casa Organizada
I3: Previsto | K3: Real | N3: Diferença
H4: Renda 1 | I4: 2398 | J4: 1940 | K4: 1940 | N4: =I4-K4 -> 458
H5: Renda 2 | I5: 2500 | J5: 2500 | K5: 2500 | N5: =I5-J5 -> 0
B6: Despesas Mensais | H6: Renda Total | I6: =+I4+I5 -> 4898 | K6: =+K4+K5 -> 4440 | N6: =+I6-K6 -> 458
H7: Despesas | I7: =+SUM(I22,O24,I29,O34,I38,O42,I51,O52,I57,O59,I64,O65,) -> 12013.3 | K7: =+SUM(J22,J29,J38,J51,J57,J64,P65,P59,P52,P42,P34,P24,) -> 3361 | N7: =+I7-K7 -> 8652.3
B8: Data | C8: Despesa | D8: Valor | E8: Área | H8: Saldo | I8: =+I6-I7 -> -7115.3 | K8: =+K6-K7 -> 1079 | N8: =I8-K8 -> -8194.3
D9: =SUM(D10:D112) -> 0
B10: 45778
B11: 45779 | H11: MORADIA | I11: Previsto | J11: Real | K11: Diferença | N11: TRANSPORTE | O11: Previsto | P11: Real | Q11: Diferença
B12: 45780 | G12: 1 | H12: Caixa de Emergência | I12: 150 | J12: =SUMIF(E$10:E$144,"1",D$10:D$144) -> 0 | K12: =+I12-J12 -> 150 | M12: 40 | N12: Uber 99 | O12: 58 | P12: 45 | Q12: =+O12-P12 -> 13
B13: 45781 | G13: 2 | H13: Inevitavelmento fixo | I13: 1200 | J13: =SUMIF(E$10:E$144,"2",D$10:D$144) -> 0 | K13: =+I13-J13 -> 1200 | M13: 41 | N13: Uber | O13: 68 | P13: =SUMIF(E$10:E$144,"41",D$10:D$144) -> 0 | Q13: =+O13-P13 -> 68
B14: 45782 | G14: 3 | H14: Das Jhenis | I14: 250 | J14: =SUMIF(E$10:E$144,"3",D$10:D$144) -> 0 | K14: =+I14-J14 -> 250 | M14: 42 | N14: Transporte Público | O14: 440 | P14: 0 | Q14: =+O14-P14 -> 440
B15: 45783 | G15: 4 | H15: Cartao Jhenismara | I15: 1200 | J15: 1400 | K15: =+I15-J15 -> -200 | M15: 43 | N15: Transporte Trabalho J | O15: 240 | P15: 143 | Q15: =+O15-P15 -> 97
B16: 45784 | G16: 5 | H16: Emergência Casa | I16: 120 | J16: =SUMIF(E$10:E$144,"5",D$10:D$144) -> 0 | K16: =+I16-J16 -> 120 | M16: 44 | N16: Transporte Trabalho M | O16: 110 | P16: 240 | Q16: =+O16-P16 -> -130
B17: 45785 | G17: 6 | H17: Energia | I17: 150 | J17: 150 | K17: =+I17-J17 -> 0 | M17: 45 | N17: Caixa Carro J | O17: 0 | P17: =SUMIF(E$10:E$144,"45",D$10:D$144) -> 0 | Q17: =+O17-P17 -> 0
B18: 45786 | G18: 7 | H18: Água | I18: 77 | J18: 77 | K18: =+I18-J18 -> 0 | M18: 46 | N18: Caixa Carro M | O18: 0 | P18: =SUMIF(E$10:E$144,"46",D$10:D$144) -> 0 | Q18: =+O18-P18 -> 0
B19: 45787 | G19: 8 | H19: Gás | I19: 55 | J19: 55 | K19: =+I19-J19 -> 0 | M19: 47 | O19: 0 | P19: =SUMIF(E$10:E$144,"47",D$10:D$144) -> 0 | Q19: =+O19-P19 -> 0
B20: 45788 | G20: 9 | H20: Cartao (Matheus) | I20: 175 | J20: 175 | K20: =+I20-J20 -> 0 | M20: 48 | O20: 0 | P20: =SUMIF(E$10:E$144,"48",D$10:D$144) -> 0 | Q20: =+O20-P20 -> 0
B21: 45789 | G21: 10 | H21: Outrs Dispesas | J21: =SUMIF(E$10:E$144,"10",D$10:D$144) -> 0 | K21: =+I21-J21 -> 0 | M21: 49 | O21: 0 | P21: 0 | Q21: =+O21-P21 -> 0
B22: 45790 | H22: TOTAL | I22: =SUM(I12:I21) -> 3377 | J22: =SUM(J12:J21) -> 1857 | K22: =+I22-J22 -> 1520 | M22: 50 | O22: 0 | P22: 0 | Q22: =+O22-P22 -> 0
B23: 45791 | M23: 51 | N23: Outros Transporte | O23: 0 | P23: =SUMIF(E$10:E$144,"51",D$10:D$144) -> 0 | Q23: =+O23-P23 -> 0
B24: 45792 | H24: ALIMENTAÇÃO | I24: Previsto | J24: Real | K24: Diferença | N24: TOTAL | O24: =SUM(O12:O23) -> 916 | P24: =SUM(P12:P23) -> 428 | Q24: =+O24-P24 -> 488
B25: 45793 | G25: 11 | H25: Supermercado | I25: 450 | J25: 450 | K25: =+I25-J25 -> 0
B26: 45794 | G26: 12 | H26: Restaurante | I26: 140 | J26: 140 | K26: =+I26-J26 -> 0 | N26: EDUCAÇÃO | O26: Previsto | P26: Real | Q26: Diferença
B27: 45795 | G27: 13 | H27: Café \ Almoço | I27: 100 | J27: 250 | K27: =+I27-J27 -> -150 | M27: 52 | N27: Mensalidades | O27: 0 | P27: =SUMIF(E$10:E$144,"52",D$10:D$144) -> 0 | Q27: =+O27-P27 -> 0
B28: 45796 | G28: 14 | H28: Pedidos IFood | I28: 140 | J28: =SUMIF(E$10:E$144,"14",D$10:D$144) -> 0 | K28: =+I28-J28 -> 140 | M28: 53 | N28: Idiomas | O28: 0 | P28: =SUMIF(E$10:E$144,"53",D$10:D$144) -> 0 | Q28: =+O28-P28 -> 0
B29: 45797 | H29: TOTAL | I29: =SUM(I25:I28) -> 830 | J29: =SUM(J25:J28) -> 840 | K29: =+I29-J29 -> -10 | M29: 54 | N29: CNH [Matheus] | O29: 0 | P29: =SUMIF(E$10:E$144,"54",D$10:D$144) -> 0 | Q29: =+O29-P29 -> 0
B30: 45798 | M30: 55 | N30: Cursos | O30: 140 | P30: =SUMIF(E$10:E$144,"55",D$10:D$144) -> 0 | Q30: =+O30-P30 -> 140
B31: 45799 | H31: COMUNICAÇÃO | I31: Previsto | J31: Real | K31: Diferença | M31: 56 | N31: Livros | O31: 0 | P31: =SUMIF(E$10:E$144,"56",D$10:D$144) -> 0 | Q31: =+O31-P31 -> 0
B32: 45800 | G32: 15 | H32: Celular | I32: 45 | J32: 45 | K32: =+I32-J32 -> 0 | M32: 57 | N32: Faculdade [Jhenis] | O32: 0 | P32: =SUMIF(E$10:E$144,"57",D$10:D$144) -> 0 | Q32: =+O32-P32 -> 0
B33: 45801 | G33: 16 | H33: Internet | I33: 89 | J33: 89 | K33: =+I33-J33 -> 0 | M33: 58 | N33: Outros Educação | O33: 0 | P33: =SUMIF(E$10:E$144,"58",D$10:D$144) -> 0 | Q33: =+O33-P33 -> 0
B34: 45802 | G34: 17 | H34: Streaming | I34: 24 | J34: 24 | K34: =+I34-J34 -> 0 | N34: TOTAL | O34: =SUM(O27:O33) -> 140 | P34: =SUM(P27:P33) -> 0 | Q34: =+O34-P34 -> 140
B35: 45803 | G35: 18 | H35: Netflix | I35: 21.9 | J35: 22 | K35: =+I35-J35 -> -0.1
B36: 45804 | G36: 19 | H36: Amazon | I36: 10.9 | J36: 11 | K36: =+I36-J36 -> -0.1 | N36: LAZER | O36: Previsto | P36: Real | Q36: Diferença
B37: 45805 | G37: 20 | H37: Max Plus | I37: 34.5 | J37: 45 | K37: =+I37-J37 -> -10.5 | M37: 60 | N37: Cinema | O37: 450 | P37: =SUMIF(E$10:E$144,"60",D$10:D$144) -> 0 | Q37: =+O37-P37 -> 450
B38: 45806 | H38: TOTAL | I38: =SUM(I32:I37) -> 225.3 | J38: =SUM(J32:J37) -> 236 | K38: =+I38-J38 -> -10.7 | M38: 61 | N38: Esportes | O38: 0 | P38: =SUMIF(E$10:E$144,"61",D$10:D$144) -> 0 | Q38: =+O38-P38 -> 0
B39: 45807 | M39: 62 | N39: Shows [Consertos] | O39: 120 | P39: =SUMIF(E$10:E$144,"62",D$10:D$144) -> 0 | Q39: =+O39-P39 -> 120
H40: SAÚDE E CUIDADOS | I40: Previsto | J40: Real | K40: Diferença | M40: 63 | N40: Viagens [Férias] | O40: 148 | P40: =SUMIF(E$10:E$144,"63",D$10:D$144) -> 0 | Q40: =+O40-P40 -> 148
G41: 21 | H41: Academia | I41: 120 | J41: =SUMIF(E$10:E$144,"21",D$10:D$144) -> 0 | K41: =+I41-J41 -> 120 | M41: 64 | N41: Outros Lazer | O41: 60 | P41: =SUMIF(E$10:E$144,"64",D$10:D$144) -> 0 | Q41: =+O41-P41 -> 60
...

Sheet JUN
B1: Lançamento de Compras e Gastos Casa Organizada
I3: Previsto | K3: Real | N3: Diferença
H4: Renda 1 | I4: 2398 | J4: 1940 | K4: 1940 | N4: =I4-K4 -> 458
H5: Renda 2 | I5: 2500 | J5: 2500 | K5: 2500 | N5: =I5-J5 -> 0
B6: Despesas Mensais | H6: Renda Total | I6: =+I4+I5 -> 4898 | K6: =+K4+K5 -> 4440 | N6: =+I6-K6 -> 458
H7: Despesas | I7: =+SUM(I22,O24,I29,O34,I38,O42,I51,O52,I57,O59,I64,O65,) -> 12013.3 | K7: =+SUM(J22,J29,J38,J51,J57,J64,P65,P59,P52,P42,P34,P24,) -> 3361 | N7: =+I7-K7 -> 8652.3
B8: Data | C8: Despesa | D8: Valor | E8: Área | H8: Saldo | I8: =+I6-I7 -> -7115.3 | K8: =+K6-K7 -> 1079 | N8: =I8-K8 -> -8194.3
D9: =SUM(D10:D112) -> 0
B10: 45809
B11: 45810 | H11: MORADIA | I11: Previsto | J11: Real | K11: Diferença | N11: TRANSPORTE | O11: Previsto | P11: Real | Q11: Diferença
B12: 45811 | G12: 1 | H12: Caixa de Emergência | I12: 150 | J12: =SUMIF(E$10:E$144,"1",D$10:D$144) -> 0 | K12: =+I12-J12 -> 150 | M12: 40 | N12: Uber 99 | O12: 58 | P12: 45 | Q12: =+O12-P12 -> 13
B13: 45812 | G13: 2 | H13: Inevitavelmento fixo | I13: 1200 | J13: =SUMIF(E$10:E$144,"2",D$10:D$144) -> 0 | K13: =+I13-J13 -> 1200 | M13: 41 | N13: Uber | O13: 68 | P13: =SUMIF(E$10:E$144,"41",D$10:D$144) -> 0 | Q13: =+O13-P13 -> 68
B14: 45813 | G14: 3 | H14: Das Jhenis | I14: 250 | J14: =SUMIF(E$10:E$144,"3",D$10:D$144) -> 0 | K14: =+I14-J14 -> 250 | M14: 42 | N14: Transporte Público | O14: 440 | P14: 0 | Q14: =+O14-P14 -> 440
B15: 45814 | G15: 4 | H15: Cartao Jhenismara | I15: 1200 | J15: 1400 | K15: =+I15-J15 -> -200 | M15: 43 | N15: Transporte Trabalho J | O15: 240 | P15: 143 | Q15: =+O15-P15 -> 97
B16: 45815 | G16: 5 | H16: Emergência Casa | I16: 120 | J16: =SUMIF(E$10:E$144,"5",D$10:D$144) -> 0 | K16: =+I16-J16 -> 120 | M16: 44 | N16: Transporte Trabalho M | O16: 110 | P16: 240 | Q16: =+O16-P16 -> -130
B17: 45816 | G17: 6 | H17: Energia | I17: 150 | J17: 150 | K17: =+I17-J17 -> 0 | M17: 45 | N17: Caixa Carro J | O17: 0 | P17: =SUMIF(E$10:E$144,"45",D$10:D$144) -> 0 | Q17: =+O17-P17 -> 0
B18: 45817 | G18: 7 | H18: Água | I18: 77 | J18: 77 | K18: =+I18-J18 -> 0 | M18: 46 | N18: Caixa Carro M | O18: 0 | P18: =SUMIF(E$10:E$144,"46",D$10:D$144) -> 0 | Q18: =+O18-P18 -> 0
B19: 45818 | G19: 8 | H19: Gás | I19: 55 | J19: 55 | K19: =+I19-J19 -> 0 | M19: 47 | O19: 0 | P19: =SUMIF(E$10:E$144,"47",D$10:D$144) -> 0 | Q19: =+O19-P19 -> 0
B20: 45819 | G20: 9 | H20: Cartao (Matheus) | I20: 175 | J20: 175 | K20: =+I20-J20 -> 0 | M20: 48 | O20: 0 | P20: =SUMIF(E$10:E$144,"48",D$10:D$144) -> 0 | Q20: =+O20-P20 -> 0
B21: 45820 | G21: 10 | H21: Outrs Dispesas | J21: =SUMIF(E$10:E$144,"10",D$10:D$144) -> 0 | K21: =+I21-J21 -> 0 | M21: 49 | O21: 0 | P21: 0 | Q21: =+O21-P21 -> 0
B22: 45821 | H22: TOTAL | I22: =SUM(I12:I21) -> 3377 | J22: =SUM(J12:J21) -> 1857 | K22: =+I22-J22 -> 1520 | M22: 50 | O22: 0 | P22: 0 | Q22: =+O22-P22 -> 0
B23: 45822 | M23: 51 | N23: Outros Transporte | O23: 0 | P23: =SUMIF(E$10:E$144,"51",D$10:D$144) -> 0 | Q23: =+O23-P23 -> 0
B24: 45823 | H24: ALIMENTAÇÃO | I24: Previsto | J24: Real | K24: Diferença | N24: TOTAL | O24: =SUM(O12:O23) -> 916 | P24: =SUM(P12:P23) -> 428 | Q24: =+O24-P24 -> 488
B25: 45824 | G25: 11 | H25: Supermercado | I25: 450 | J25: 450 | K25: =+I25-J25 -> 0
B26: 45825 | G26: 12 | H26: Restaurante | I26: 140 | J26: 140 | K26: =+I26-J26 -> 0 | N26: EDUCAÇÃO | O26: Previsto | P26: Real | Q26: Diferença
B27: 45826 | G27: 13 | H27: Café \ Almoço | I27: 100 | J27: 250 | K27: =+I27-J27 -> -150 | M27: 52 | N27: Mensalidades | O27: 0 | P27: =SUMIF(E$10:E$144,"52",D$10:D$144) -> 0 | Q27: =+O27-P27 -> 0
B28: 45827 | G28: 14 | H28: Pedidos IFood | I28: 140 | J28: =SUMIF(E$10:E$144,"14",D$10:D$144) -> 0 | K28: =+I28-J28 -> 140 | M28: 53 | N28: Idiomas | O28: 0 | P28: =SUMIF(E$10:E$144,"53",D$10:D$144) -> 0 | Q28: =+O28-P28 -> 0
B29: 45828 | H29: TOTAL | I29: =SUM(I25:I28) -> 830 | J29: =SUM(J25:J28) -> 840 | K29: =+I29-J29 -> -10 | M29: 54 | N29: CNH [Matheus] | O29: 0 | P29: =SUMIF(E$10:E$144,"54",D$10:D$144) -> 0 | Q29: =+O29-P29 -> 0
B30: 45829 | M30: 55 | N30: Cursos | O30: 140 | P30: =SUMIF(E$10:E$144,"55",D$10:D$144) -> 0 | Q30: =+O30-P30 -> 140
B31: 45830 | H31: COMUNICAÇÃO | I31: Previsto | J31: Real | K31: Diferença | M31: 56 | N31: Livros | O31: 0 | P31: =SUMIF(E$10:E$144,"56",D$10:D$144) -> 0 | Q31: =+O31-P31 -> 0
B32: 45831 | G32: 15 | H32: Celular | I32: 45 | J32: 45 | K32: =+I32-J32 -> 0 | M32: 57 | N32: Faculdade [Jhenis] | O32: 0 | P32: =SUMIF(E$10:E$144,"57",D$10:D$144) -> 0 | Q32: =+O32-P32 -> 0
B33: 45832 | G33: 16 | H33: Internet | I33: 89 | J33: 89 | K33: =+I33-J33 -> 0 | M33: 58 | N33: Outros Educação | O33: 0 | P33: =SUMIF(E$10:E$144,"58",D$10:D$144) -> 0 | Q33: =+O33-P33 -> 0
B34: 45833 | G34: 17 | H34: Streaming | I34: 24 | J34: 24 | K34: =+I34-J34 -> 0 | N34: TOTAL | O34: =SUM(O27:O33) -> 140 | P34: =SUM(P27:P33) -> 0 | Q34: =+O34-P34 -> 140
B35: 45834 | G35: 18 | H35: Netflix | I35: 21.9 | J35: 22 | K35: =+I35-J35 -> -0.1
B36: 45835 | G36: 19 | H36: Amazon | I36: 10.9 | J36: 11 | K36: =+I36-J36 -> -0.1 | N36: LAZER | O36: Previsto | P36: Real | Q36: Diferença
B37: 45836 | G37: 20 | H37: Max Plus | I37: 34.5 | J37: 45 | K37: =+I37-J37 -> -10.5 | M37: 60 | N37: Cinema | O37: 450 | P37: =SUMIF(E$10:E$144,"60",D$10:D$144) -> 0 | Q37: =+O37-P37 -> 450
B38: 45837 | H38: TOTAL | I38: =SUM(I32:I37) -> 225.3 | J38: =SUM(J32:J37) -> 236 | K38: =+I38-J38 -> -10.7 | M38: 61 | N38: Esportes | O38: 0 | P38: =SUMIF(E$10:E$144,"61",D$10:D$144) -> 0 | Q38: =+O38-P38 -> 0
B39: 45838 | M39: 62 | N39: Shows [Consertos] | O39: 120 | P39: =SUMIF(E$10:E$144,"62",D$10:D$144) -> 0 | Q39: =+O39-P39 -> 120
H40: SAÚDE E CUIDADOS | I40: Previsto | J40: Real | K40: Diferença | M40: 63 | N40: Viagens [Férias] | O40: 148 | P40: =SUMIF(E$10:E$144,"63",D$10:D$144) -> 0 | Q40: =+O40-P40 -> 148
G41: 21 | H41: Academia | I41: 120 | J41: =SUMIF(E$10:E$144,"21",D$10:D$144) -> 0 | K41: =+I41-J41 -> 120 | M41: 64 | N41: Outros Lazer | O41: 60 | P41: =SUMIF(E$10:E$144,"64",D$10:D$144) -> 0 | Q41: =+O41-P41 -> 60
...

Sheet JUL
B1: Lançamento de Compras e Gastos Casa Organizada
I3: Previsto | K3: Real | N3: Diferença
H4: Renda 1 | I4: 2398 | J4: 1940 | K4: 1940 | N4: =I4-K4 -> 458
H5: Renda 2 | I5: 2500 | J5: 2500 | K5: 2500 | N5: =I5-J5 -> 0
B6: Despesas Mensais | H6: Renda Total | I6: =+I4+I5 -> 4898 | K6: =+K4+K5 -> 4440 | N6: =+I6-K6 -> 458
H7: Despesas | I7: =+SUM(I22,O24,I29,O34,I38,O42,I51,O52,I57,O59,I64,O65,) -> 12013.3 | K7: =+SUM(J22,J29,J38,J51,J57,J64,P65,P59,P52,P42,P34,P24,) -> 3361 | N7: =+I7-K7 -> 8652.3
B8: Data | C8: Despesa | D8: Valor | E8: Área | H8: Saldo | I8: =+I6-I7 -> -7115.3 | K8: =+K6-K7 -> 1079 | N8: =I8-K8 -> -8194.3
D9: =SUM(D10:D112) -> 0
B10: 45839
B11: 45840 | H11: MORADIA | I11: Previsto | J11: Real | K11: Diferença | N11: TRANSPORTE | O11: Previsto | P11: Real | Q11: Diferença
B12: 45841 | G12: 1 | H12: Caixa de Emergência | I12: 150 | J12: =SUMIF(E$10:E$144,"1",D$10:D$144) -> 0 | K12: =+I12-J12 -> 150 | M12: 40 | N12: Uber 99 | O12: 58 | P12: 45 | Q12: =+O12-P12 -> 13
B13: 45842 | G13: 2 | H13: Inevitavelmento fixo | I13: 1200 | J13: =SUMIF(E$10:E$144,"2",D$10:D$144) -> 0 | K13: =+I13-J13 -> 1200 | M13: 41 | N13: Uber | O13: 68 | P13: =SUMIF(E$10:E$144,"41",D$10:D$144) -> 0 | Q13: =+O13-P13 -> 68
B14: 45843 | G14: 3 | H14: Das Jhenis | I14: 250 | J14: =SUMIF(E$10:E$144,"3",D$10:D$144) -> 0 | K14: =+I14-J14 -> 250 | M14: 42 | N14: Transporte Público | O14: 440 | P14: 0 | Q14: =+O14-P14 -> 440
B15: 45844 | G15: 4 | H15: Cartao Jhenismara | I15: 1200 | J15: 1400 | K15: =+I15-J15 -> -200 | M15: 43 | N15: Transporte Trabalho J | O15: 240 | P15: 143 | Q15: =+O15-P15 -> 97
B16: 45845 | G16: 5 | H16: Emergência Casa | I16: 120 | J16: =SUMIF(E$10:E$144,"5",D$10:D$144) -> 0 | K16: =+I16-J16 -> 120 | M16: 44 | N16: Transporte Trabalho M | O16: 110 | P16: 240 | Q16: =+O16-P16 -> -130
B17: 45846 | G17: 6 | H17: Energia | I17: 150 | J17: 150 | K17: =+I17-J17 -> 0 | M17: 45 | N17: Caixa Carro J | O17: 0 | P17: =SUMIF(E$10:E$144,"45",D$10:D$144) -> 0 | Q17: =+O17-P17 -> 0
B18: 45847 | G18: 7 | H18: Água | I18: 77 | J18: 77 | K18: =+I18-J18 -> 0 | M18: 46 | N18: Caixa Carro M | O18: 0 | P18: =SUMIF(E$10:E$144,"46",D$10:D$144) -> 0 | Q18: =+O18-P18 -> 0
B19: 45848 | G19: 8 | H19: Gás | I19: 55 | J19: 55 | K19: =+I19-J19 -> 0 | M19: 47 | O19: 0 | P19: =SUMIF(E$10:E$144,"47",D$10:D$144) -> 0 | Q19: =+O19-P19 -> 0
B20: 45849 | G20: 9 | H20: Cartao (Matheus) | I20: 175 | J20: 175 | K20: =+I20-J20 -> 0 | M20: 48 | O20: 0 | P20: =SUMIF(E$10:E$144,"48",D$10:D$144) -> 0 | Q20: =+O20-P20 -> 0
B21: 45850 | G21: 10 | H21: Outrs Dispesas | J21: =SUMIF(E$10:E$144,"10",D$10:D$144) -> 0 | K21: =+I21-J21 -> 0 | M21: 49 | O21: 0 | P21: 0 | Q21: =+O21-P21 -> 0
B22: 45851 | H22: TOTAL | I22: =SUM(I12:I21) -> 3377 | J22: =SUM(J12:J21) -> 1857 | K22: =+I22-J22 -> 1520 | M22: 50 | O22: 0 | P22: 0 | Q22: =+O22-P22 -> 0
B23: 45852 | M23: 51 | N23: Outros Transporte | O23: 0 | P23: =SUMIF(E$10:E$144,"51",D$10:D$144) -> 0 | Q23: =+O23-P23 -> 0
B24: 45853 | H24: ALIMENTAÇÃO | I24: Previsto | J24: Real | K24: Diferença | N24: TOTAL | O24: =SUM(O12:O23) -> 916 | P24: =SUM(P12:P23) -> 428 | Q24: =+O24-P24 -> 488
B25: 45854 | G25: 11 | H25: Supermercado | I25: 450 | J25: 450 | K25: =+I25-J25 -> 0
B26: 45855 | G26: 12 | H26: Restaurante | I26: 140 | J26: 140 | K26: =+I26-J26 -> 0 | N26: EDUCAÇÃO | O26: Previsto | P26: Real | Q26: Diferença
B27: 45856 | G27: 13 | H27: Café \ Almoço | I27: 100 | J27: 250 | K27: =+I27-J27 -> -150 | M27: 52 | N27: Mensalidades | O27: 0 | P27: =SUMIF(E$10:E$144,"52",D$10:D$144) -> 0 | Q27: =+O27-P27 -> 0
B28: 45857 | G28: 14 | H28: Pedidos IFood | I28: 140 | J28: =SUMIF(E$10:E$144,"14",D$10:D$144) -> 0 | K28: =+I28-J28 -> 140 | M28: 53 | N28: Idiomas | O28: 0 | P28: =SUMIF(E$10:E$144,"53",D$10:D$144) -> 0 | Q28: =+O28-P28 -> 0
B29: 45858 | H29: TOTAL | I29: =SUM(I25:I28) -> 830 | J29: =SUM(J25:J28) -> 840 | K29: =+I29-J29 -> -10 | M29: 54 | N29: CNH [Matheus] | O29: 0 | P29: =SUMIF(E$10:E$144,"54",D$10:D$144) -> 0 | Q29: =+O29-P29 -> 0
B30: 45859 | M30: 55 | N30: Cursos | O30: 140 | P30: =SUMIF(E$10:E$144,"55",D$10:D$144) -> 0 | Q30: =+O30-P30 -> 140
B31: 45860 | H31: COMUNICAÇÃO | I31: Previsto | J31: Real | K31: Diferença | M31: 56 | N31: Livros | O31: 0 | P31: =SUMIF(E$10:E$144,"56",D$10:D$144) -> 0 | Q31: =+O31-P31 -> 0
B32: 45861 | G32: 15 | H32: Celular | I32: 45 | J32: 45 | K32: =+I32-J32 -> 0 | M32: 57 | N32: Faculdade [Jhenis] | O32: 0 | P32: =SUMIF(E$10:E$144,"57",D$10:D$144) -> 0 | Q32: =+O32-P32 -> 0
B33: 45862 | G33: 16 | H33: Internet | I33: 89 | J33: 89 | K33: =+I33-J33 -> 0 | M33: 58 | N33: Outros Educação | O33: 0 | P33: =SUMIF(E$10:E$144,"58",D$10:D$144) -> 0 | Q33: =+O33-P33 -> 0
B34: 45863 | G34: 17 | H34: Streaming | I34: 24 | J34: 24 | K34: =+I34-J34 -> 0 | N34: TOTAL | O34: =SUM(O27:O33) -> 140 | P34: =SUM(P27:P33) -> 0 | Q34: =+O34-P34 -> 140
B35: 45864 | G35: 18 | H35: Netflix | I35: 21.9 | J35: 22 | K35: =+I35-J35 -> -0.1
B36: 45865 | G36: 19 | H36: Amazon | I36: 10.9 | J36: 11 | K36: =+I36-J36 -> -0.1 | N36: LAZER | O36: Previsto | P36: Real | Q36: Diferença
B37: 45866 | G37: 20 | H37: Max Plus | I37: 34.5 | J37: 45 | K37: =+I37-J37 -> -10.5 | M37: 60 | N37: Cinema | O37: 450 | P37: =SUMIF(E$10:E$144,"60",D$10:D$144) -> 0 | Q37: =+O37-P37 -> 450
B38: 45867 | H38: TOTAL | I38: =SUM(I32:I37) -> 225.3 | J38: =SUM(J32:J37) -> 236 | K38: =+I38-J38 -> -10.7 | M38: 61 | N38: Esportes | O38: 0 | P38: =SUMIF(E$10:E$144,"61",D$10:D$144) -> 0 | Q38: =+O38-P38 -> 0
B39: 45868 | M39: 62 | N39: Shows [Consertos] | O39: 120 | P39: =SUMIF(E$10:E$144,"62",D$10:D$144) -> 0 | Q39: =+O39-P39 -> 120
B40: 45869 | H40: SAÚDE E CUIDADOS | I40: Previsto | J40: Real | K40: Diferença | M40: 63 | N40: Viagens [Férias] | O40: 148 | P40: =SUMIF(E$10:E$144,"63",D$10:D$144) -> 0 | Q40: =+O40-P40 -> 148
G41: 21 | H41: Academia | I41: 120 | J41: =SUMIF(E$10:E$144,"21",D$10:D$144) -> 0 | K41: =+I41-J41 -> 120 | M41: 64 | N41: Outros Lazer | O41: 60 | P41: =SUMIF(E$10:E$144,"64",D$10:D$144) -> 0 | Q41: =+O41-P41 -> 60
...

Sheet AGO
B1: Lançamento de Compras e Gastos Casa Organizada
I3: Previsto | K3: Real | N3: Diferença
H4: Renda 1 | I4: 2398 | J4: 1940 | K4: 1940 | N4: =I4-K4 -> 458
H5: Renda 2 | I5: 2500 | J5: 2500 | K5: 2500 | N5: =I5-J5 -> 0
B6: Despesas Mensais | H6: Renda Total | I6: =+I4+I5 -> 4898 | K6: =+K4+K5 -> 4440 | N6: =+I6-K6 -> 458
H7: Despesas | I7: =+SUM(I22,O24,I29,O34,I38,O42,I51,O52,I57,O59,I64,O65,) -> 12013.3 | K7: =+SUM(J22,J29,J38,J51,J57,J64,P65,P59,P52,P42,P34,P24,) -> 3361 | N7: =+I7-K7 -> 8652.3
B8: Data | C8: Despesa | D8: Valor | E8: Área | H8: Saldo | I8: =+I6-I7 -> -7115.3 | K8: =+K6-K7 -> 1079 | N8: =I8-K8 -> -8194.3
D9: =SUM(D10:D112) -> 0
B10: 45870
B11: 45871 | H11: MORADIA | I11: Previsto | J11: Real | K11: Diferença | N11: TRANSPORTE | O11: Previsto | P11: Real | Q11: Diferença
B12: 45872 | G12: 1 | H12: Caixa de Emergência | I12: 150 | J12: =SUMIF(E$10:E$144,"1",D$10:D$144) -> 0 | K12: =+I12-J12 -> 150 | M12: 40 | N12: Uber 99 | O12: 58 | P12: 45 | Q12: =+O12-P12 -> 13
B13: 45873 | G13: 2 | H13: Inevitavelmento fixo | I13: 1200 | J13: =SUMIF(E$10:E$144,"2",D$10:D$144) -> 0 | K13: =+I13-J13 -> 1200 | M13: 41 | N13: Uber | O13: 68 | P13: =SUMIF(E$10:E$144,"41",D$10:D$144) -> 0 | Q13: =+O13-P13 -> 68
B14: 45874 | G14: 3 | H14: Das Jhenis | I14: 250 | J14: =SUMIF(E$10:E$144,"3",D$10:D$144) -> 0 | K14: =+I14-J14 -> 250 | M14: 42 | N14: Transporte Público | O14: 440 | P14: 0 | Q14: =+O14-P14 -> 440
B15: 45875 | G15: 4 | H15: Cartao Jhenismara | I15: 1200 | J15: 1400 | K15: =+I15-J15 -> -200 | M15: 43 | N15: Transporte Trabalho J | O15: 240 | P15: 143 | Q15: =+O15-P15 -> 97
B16: 45876 | G16: 5 | H16: Emergência Casa | I16: 120 | J16: =SUMIF(E$10:E$144,"5",D$10:D$144) -> 0 | K16: =+I16-J16 -> 120 | M16: 44 | N16: Transporte Trabalho M | O16: 110 | P16: 240 | Q16: =+O16-P16 -> -130
B17: 45877 | G17: 6 | H17: Energia | I17: 150 | J17: 150 | K17: =+I17-J17 -> 0 | M17: 45 | N17: Caixa Carro J | O17: 0 | P17: =SUMIF(E$10:E$144,"45",D$10:D$144) -> 0 | Q17: =+O17-P17 -> 0
B18: 45878 | G18: 7 | H18: Água | I18: 77 | J18: 77 | K18: =+I18-J18 -> 0 | M18: 46 | N18: Caixa Carro M | O18: 0 | P18: =SUMIF(E$10:E$144,"46",D$10:D$144) -> 0 | Q18: =+O18-P18 -> 0
B19: 45879 | G19: 8 | H19: Gás | I19: 55 | J19: 55 | K19: =+I19-J19 -> 0 | M19: 47 | O19: 0 | P19: =SUMIF(E$10:E$144,"47",D$10:D$144) -> 0 | Q19: =+O19-P19 -> 0
B20: 45880 | G20: 9 | H20: Cartao (Matheus) | I20: 175 | J20: 175 | K20: =+I20-J20 -> 0 | M20: 48 | O20: 0 | P20: =SUMIF(E$10:E$144,"48",D$10:D$144) -> 0 | Q20: =+O20-P20 -> 0
B21: 45881 | G21: 10 | H21: Outrs Dispesas | J21: =SUMIF(E$10:E$144,"10",D$10:D$144) -> 0 | K21: =+I21-J21 -> 0 | M21: 49 | O21: 0 | P21: 0 | Q21: =+O21-P21 -> 0
B22: 45882 | H22: TOTAL | I22: =SUM(I12:I21) -> 3377 | J22: =SUM(J12:J21) -> 1857 | K22: =+I22-J22 -> 1520 | M22: 50 | O22: 0 | P22: 0 | Q22: =+O22-P22 -> 0
B23: 45883 | M23: 51 | N23: Outros Transporte | O23: 0 | P23: =SUMIF(E$10:E$144,"51",D$10:D$144) -> 0 | Q23: =+O23-P23 -> 0
B24: 45884 | H24: ALIMENTAÇÃO | I24: Previsto | J24: Real | K24: Diferença | N24: TOTAL | O24: =SUM(O12:O23) -> 916 | P24: =SUM(P12:P23) -> 428 | Q24: =+O24-P24 -> 488
B25: 45885 | G25: 11 | H25: Supermercado | I25: 450 | J25: 450 | K25: =+I25-J25 -> 0
B26: 45886 | G26: 12 | H26: Restaurante | I26: 140 | J26: 140 | K26: =+I26-J26 -> 0 | N26: EDUCAÇÃO | O26: Previsto | P26: Real | Q26: Diferença
B27: 45887 | G27: 13 | H27: Café \ Almoço | I27: 100 | J27: 250 | K27: =+I27-J27 -> -150 | M27: 52 | N27: Mensalidades | O27: 0 | P27: =SUMIF(E$10:E$144,"52",D$10:D$144) -> 0 | Q27: =+O27-P27 -> 0
B28: 45888 | G28: 14 | H28: Pedidos IFood | I28: 140 | J28: =SUMIF(E$10:E$144,"14",D$10:D$144) -> 0 | K28: =+I28-J28 -> 140 | M28: 53 | N28: Idiomas | O28: 0 | P28: =SUMIF(E$10:E$144,"53",D$10:D$144) -> 0 | Q28: =+O28-P28 -> 0
B29: 45889 | H29: TOTAL | I29: =SUM(I25:I28) -> 830 | J29: =SUM(J25:J28) -> 840 | K29: =+I29-J29 -> -10 | M29: 54 | N29: CNH [Matheus] | O29: 0 | P29: =SUMIF(E$10:E$144,"54",D$10:D$144) -> 0 | Q29: =+O29-P29 -> 0
B30: 45890 | M30: 55 | N30: Cursos | O30: 140 | P30: =SUMIF(E$10:E$144,"55",D$10:D$144) -> 0 | Q30: =+O30-P30 -> 140
B31: 45891 | H31: COMUNICAÇÃO | I31: Previsto | J31: Real | K31: Diferença | M31: 56 | N31: Livros | O31: 0 | P31: =SUMIF(E$10:E$144,"56",D$10:D$144) -> 0 | Q31: =+O31-P31 -> 0
B32: 45892 | G32: 15 | H32: Celular | I32: 45 | J32: 45 | K32: =+I32-J32 -> 0 | M32: 57 | N32: Faculdade [Jhenis] | O32: 0 | P32: =SUMIF(E$10:E$144,"57",D$10:D$144) -> 0 | Q32: =+O32-P32 -> 0
B33: 45893 | G33: 16 | H33: Internet | I33: 89 | J33: 89 | K33: =+I33-J33 -> 0 | M33: 58 | N33: Outros Educação | O33: 0 | P33: =SUMIF(E$10:E$144,"58",D$10:D$144) -> 0 | Q33: =+O33-P33 -> 0
B34: 45894 | G34: 17 | H34: Streaming | I34: 24 | J34: 24 | K34: =+I34-J34 -> 0 | N34: TOTAL | O34: =SUM(O27:O33) -> 140 | P34: =SUM(P27:P33) -> 0 | Q34: =+O34-P34 -> 140
B35: 45895 | G35: 18 | H35: Netflix | I35: 21.9 | J35: 22 | K35: =+I35-J35 -> -0.1
B36: 45896 | G36: 19 | H36: Amazon | I36: 10.9 | J36: 11 | K36: =+I36-J36 -> -0.1 | N36: LAZER | O36: Previsto | P36: Real | Q36: Diferença
B37: 45897 | G37: 20 | H37: Max Plus | I37: 34.5 | J37: 45 | K37: =+I37-J37 -> -10.5 | M37: 60 | N37: Cinema | O37: 450 | P37: =SUMIF(E$10:E$144,"60",D$10:D$144) -> 0 | Q37: =+O37-P37 -> 450
B38: 45898 | H38: TOTAL | I38: =SUM(I32:I37) -> 225.3 | J38: =SUM(J32:J37) -> 236 | K38: =+I38-J38 -> -10.7 | M38: 61 | N38: Esportes | O38: 0 | P38: =SUMIF(E$10:E$144,"61",D$10:D$144) -> 0 | Q38: =+O38-P38 -> 0
B39: 45899 | M39: 62 | N39: Shows [Consertos] | O39: 120 | P39: =SUMIF(E$10:E$144,"62",D$10:D$144) -> 0 | Q39: =+O39-P39 -> 120
B40: 45900 | H40: SAÚDE E CUIDADOS | I40: Previsto | J40: Real | K40: Diferença | M40: 63 | N40: Viagens [Férias] | O40: 148 | P40: =SUMIF(E$10:E$144,"63",D$10:D$144) -> 0 | Q40: =+O40-P40 -> 148
G41: 21 | H41: Academia | I41: 120 | J41: =SUMIF(E$10:E$144,"21",D$10:D$144) -> 0 | K41: =+I41-J41 -> 120 | M41: 64 | N41: Outros Lazer | O41: 60 | P41: =SUMIF(E$10:E$144,"64",D$10:D$144) -> 0 | Q41: =+O41-P41 -> 60
...

Sheet SET
B1: Lançamento de Compras e Gastos Casa Organizada
I3: Previsto | K3: Real | N3: Diferença
H4: Renda 1 | I4: 2398 | J4: 1940 | K4: 1940 | N4: =I4-K4 -> 458
H5: Renda 2 | I5: 2500 | J5: 2500 | K5: 2500 | N5: =I5-J5 -> 0
B6: Despesas Mensais | H6: Renda Total | I6: =+I4+I5 -> 4898 | K6: =+K4+K5 -> 4440 | N6: =+I6-K6 -> 458
H7: Despesas | I7: =+SUM(I22,O24,I29,O34,I38,O42,I51,O52,I57,O59,I64,O65,) -> 12013.3 | K7: =+SUM(J22,J29,J38,J51,J57,J64,P65,P59,P52,P42,P34,P24,) -> 3361 | N7: =+I7-K7 -> 8652.3
B8: Data | C8: Despesa | D8: Valor | E8: Área | H8: Saldo | I8: =+I6-I7 -> -7115.3 | K8: =+K6-K7 -> 1079 | N8: =I8-K8 -> -8194.3
D9: =SUM(D10:D112) -> 0
B10: 45901
B11: 45902 | H11: MORADIA | I11: Previsto | J11: Real | K11: Diferença | N11: TRANSPORTE | O11: Previsto | P11: Real | Q11: Diferença
B12: 45903 | G12: 1 | H12: Caixa de Emergência | I12: 150 | J12: =SUMIF(E$10:E$144,"1",D$10:D$144) -> 0 | K12: =+I12-J12 -> 150 | M12: 40 | N12: Uber 99 | O12: 58 | P12: 45 | Q12: =+O12-P12 -> 13
B13: 45904 | G13: 2 | H13: Inevitavelmento fixo | I13: 1200 | J13: =SUMIF(E$10:E$144,"2",D$10:D$144) -> 0 | K13: =+I13-J13 -> 1200 | M13: 41 | N13: Uber | O13: 68 | P13: =SUMIF(E$10:E$144,"41",D$10:D$144) -> 0 | Q13: =+O13-P13 -> 68
B14: 45905 | G14: 3 | H14: Das Jhenis | I14: 250 | J14: =SUMIF(E$10:E$144,"3",D$10:D$144) -> 0 | K14: =+I14-J14 -> 250 | M14: 42 | N14: Transporte Público | O14: 440 | P14: 0 | Q14: =+O14-P14 -> 440
B15: 45906 | G15: 4 | H15: Cartao Jhenismara | I15: 1200 | J15: 1400 | K15: =+I15-J15 -> -200 | M15: 43 | N15: Transporte Trabalho J | O15: 240 | P15: 143 | Q15: =+O15-P15 -> 97
B16: 45907 | G16: 5 | H16: Emergência Casa | I16: 120 | J16: =SUMIF(E$10:E$144,"5",D$10:D$144) -> 0 | K16: =+I16-J16 -> 120 | M16: 44 | N16: Transporte Trabalho M | O16: 110 | P16: 240 | Q16: =+O16-P16 -> -130
B17: 45908 | G17: 6 | H17: Energia | I17: 150 | J17: 150 | K17: =+I17-J17 -> 0 | M17: 45 | N17: Caixa Carro J | O17: 0 | P17: =SUMIF(E$10:E$144,"45",D$10:D$144) -> 0 | Q17: =+O17-P17 -> 0
B18: 45909 | G18: 7 | H18: Água | I18: 77 | J18: 77 | K18: =+I18-J18 -> 0 | M18: 46 | N18: Caixa Carro M | O18: 0 | P18: =SUMIF(E$10:E$144,"46",D$10:D$144) -> 0 | Q18: =+O18-P18 -> 0
B19: 45910 | G19: 8 | H19: Gás | I19: 55 | J19: 55 | K19: =+I19-J19 -> 0 | M19: 47 | O19: 0 | P19: =SUMIF(E$10:E$144,"47",D$10:D$144) -> 0 | Q19: =+O19-P19 -> 0
B20: 45911 | G20: 9 | H20: Cartao (Matheus) | I20: 175 | J20: 175 | K20: =+I20-J20 -> 0 | M20: 48 | O20: 0 | P20: =SUMIF(E$10:E$144,"48",D$10:D$144) -> 0 | Q20: =+O20-P20 -> 0
B21: 45912 | G21: 10 | H21: Outrs Dispesas | J21: =SUMIF(E$10:E$144,"10",D$10:D$144) -> 0 | K21: =+I21-J21 -> 0 | M21: 49 | O21: 0 | P21: 0 | Q21: =+O21-P21 -> 0
B22: 45913 | H22: TOTAL | I22: =SUM(I12:I21) -> 3377 | J22: =SUM(J12:J21) -> 1857 | K22: =+I22-J22 -> 1520 | M22: 50 | O22: 0 | P22: 0 | Q22: =+O22-P22 -> 0
B23: 45914 | M23: 51 | N23: Outros Transporte | O23: 0 | P23: =SUMIF(E$10:E$144,"51",D$10:D$144) -> 0 | Q23: =+O23-P23 -> 0
B24: 45915 | H24: ALIMENTAÇÃO | I24: Previsto | J24: Real | K24: Diferença | N24: TOTAL | O24: =SUM(O12:O23) -> 916 | P24: =SUM(P12:P23) -> 428 | Q24: =+O24-P24 -> 488
B25: 45916 | G25: 11 | H25: Supermercado | I25: 450 | J25: 450 | K25: =+I25-J25 -> 0
B26: 45917 | G26: 12 | H26: Restaurante | I26: 140 | J26: 140 | K26: =+I26-J26 -> 0 | N26: EDUCAÇÃO | O26: Previsto | P26: Real | Q26: Diferença
B27: 45918 | G27: 13 | H27: Café \ Almoço | I27: 100 | J27: 250 | K27: =+I27-J27 -> -150 | M27: 52 | N27: Mensalidades | O27: 0 | P27: =SUMIF(E$10:E$144,"52",D$10:D$144) -> 0 | Q27: =+O27-P27 -> 0
B28: 45919 | G28: 14 | H28: Pedidos IFood | I28: 140 | J28: =SUMIF(E$10:E$144,"14",D$10:D$144) -> 0 | K28: =+I28-J28 -> 140 | M28: 53 | N28: Idiomas | O28: 0 | P28: =SUMIF(E$10:E$144,"53",D$10:D$144) -> 0 | Q28: =+O28-P28 -> 0
B29: 45920 | H29: TOTAL | I29: =SUM(I25:I28) -> 830 | J29: =SUM(J25:J28) -> 840 | K29: =+I29-J29 -> -10 | M29: 54 | N29: CNH [Matheus] | O29: 0 | P29: =SUMIF(E$10:E$144,"54",D$10:D$144) -> 0 | Q29: =+O29-P29 -> 0
B30: 45921 | M30: 55 | N30: Cursos | O30: 140 | P30: =SUMIF(E$10:E$144,"55",D$10:D$144) -> 0 | Q30: =+O30-P30 -> 140
B31: 45922 | H31: COMUNICAÇÃO | I31: Previsto | J31: Real | K31: Diferença | M31: 56 | N31: Livros | O31: 0 | P31: =SUMIF(E$10:E$144,"56",D$10:D$144) -> 0 | Q31: =+O31-P31 -> 0
B32: 45923 | G32: 15 | H32: Celular | I32: 45 | J32: 45 | K32: =+I32-J32 -> 0 | M32: 57 | N32: Faculdade [Jhenis] | O32: 0 | P32: =SUMIF(E$10:E$144,"57",D$10:D$144) -> 0 | Q32: =+O32-P32 -> 0
B33: 45924 | G33: 16 | H33: Internet | I33: 89 | J33: 89 | K33: =+I33-J33 -> 0 | M33: 58 | N33: Outros Educação | O33: 0 | P33: =SUMIF(E$10:E$144,"58",D$10:D$144) -> 0 | Q33: =+O33-P33 -> 0
B34: 45925 | G34: 17 | H34: Streaming | I34: 24 | J34: 24 | K34: =+I34-J34 -> 0 | N34: TOTAL | O34: =SUM(O27:O33) -> 140 | P34: =SUM(P27:P33) -> 0 | Q34: =+O34-P34 -> 140
B35: 45926 | G35: 18 | H35: Netflix | I35: 21.9 | J35: 22 | K35: =+I35-J35 -> -0.1
B36: 45927 | G36: 19 | H36: Amazon | I36: 10.9 | J36: 11 | K36: =+I36-J36 -> -0.1 | N36: LAZER | O36: Previsto | P36: Real | Q36: Diferença
B37: 45928 | G37: 20 | H37: Max Plus | I37: 34.5 | J37: 45 | K37: =+I37-J37 -> -10.5 | M37: 60 | N37: Cinema | O37: 450 | P37: =SUMIF(E$10:E$144,"60",D$10:D$144) -> 0 | Q37: =+O37-P37 -> 450
B38: 45929 | H38: TOTAL | I38: =SUM(I32:I37) -> 225.3 | J38: =SUM(J32:J37) -> 236 | K38: =+I38-J38 -> -10.7 | M38: 61 | N38: Esportes | O38: 0 | P38: =SUMIF(E$10:E$144,"61",D$10:D$144) -> 0 | Q38: =+O38-P38 -> 0
B39: 45930 | M39: 62 | N39: Shows [Consertos] | O39: 120 | P39: =SUMIF(E$10:E$144,"62",D$10:D$144) -> 0 | Q39: =+O39-P39 -> 120
H40: SAÚDE E CUIDADOS | I40: Previsto | J40: Real | K40: Diferença | M40: 63 | N40: Viagens [Férias] | O40: 148 | P40: =SUMIF(E$10:E$144,"63",D$10:D$144) -> 0 | Q40: =+O40-P40 -> 148
G41: 21 | H41: Academia | I41: 120 | J41: =SUMIF(E$10:E$144,"21",D$10:D$144) -> 0 | K41: =+I41-J41 -> 120 | M41: 64 | N41: Outros Lazer | O41: 60 | P41: =SUMIF(E$10:E$144,"64",D$10:D$144) -> 0 | Q41: =+O41-P41 -> 60
...

Sheet OUT
B1: Lançamento de Compras e Gastos Casa Organizada
I3: Previsto | K3: Real | N3: Diferença
H4: Renda 1 | I4: 2398 | J4: 1940 | K4: 1940 | N4: =I4-K4 -> 458
H5: Renda 2 | I5: 2500 | J5: 2500 | K5: 2500 | N5: =I5-J5 -> 0
B6: Despesas Mensais | H6: Renda Total | I6: =+I4+I5 -> 4898 | K6: =+K4+K5 -> 4440 | N6: =+I6-K6 -> 458
H7: Despesas | I7: =+SUM(I22,O24,I29,O34,I38,O42,I51,O52,I57,O59,I64,O65,) -> 12013.3 | K7: =+SUM(J22,J29,J38,J51,J57,J64,P65,P59,P52,P42,P34,P24,) -> 3361 | N7: =+I7-K7 -> 8652.3
B8: Data | C8: Despesa | D8: Valor | E8: Área | H8: Saldo | I8: =+I6-I7 -> -7115.3 | K8: =+K6-K7 -> 1079 | N8: =I8-K8 -> -8194.3
D9: =SUM(D10:D107) -> 0
B10: 45566
B11: 45567 | H11: MORADIA | I11: Previsto | J11: Real | K11: Diferença | N11: TRANSPORTE | O11: Previsto | P11: Real | Q11: Diferença
B12: 45568 | G12: 1 | H12: Caixa de Emergência | I12: 150 | J12: =SUMIF(E$10:E$144,"1",D$10:D$144) -> 0 | K12: =+I12-J12 -> 150 | M12: 40 | N12: Uber 99 | O12: 58 | P12: 45 | Q12: =+O12-P12 -> 13
B13: 45574 | G13: 2 | H13: Inevitavelmento fixo | I13: 1200 | J13: =SUMIF(E$10:E$144,"2",D$10:D$144) -> 0 | K13: =+I13-J13 -> 1200 | M13: 41 | N13: Uber | O13: 68 | P13: =SUMIF(E$10:E$144,"41",D$10:D$144) -> 0 | Q13: =+O13-P13 -> 68
B14: 45575 | G14: 3 | H14: Das Jhenis | I14: 250 | J14: =SUMIF(E$10:E$144,"3",D$10:D$144) -> 0 | K14: =+I14-J14 -> 250 | M14: 42 | N14: Transporte Público | O14: 440 | P14: 0 | Q14: =+O14-P14 -> 440
B15: 45576 | G15: 4 | H15: Cartao Jhenismara | I15: 1200 | J15: 1400 | K15: =+I15-J15 -> -200 | M15: 43 | N15: Transporte Trabalho J | O15: 240 | P15: 143 | Q15: =+O15-P15 -> 97
B16: 45577 | G16: 5 | H16: Emergência Casa | I16: 120 | J16: =SUMIF(E$10:E$144,"5",D$10:D$144) -> 0 | K16: =+I16-J16 -> 120 | M16: 44 | N16: Transporte Trabalho M | O16: 110 | P16: 240 | Q16: =+O16-P16 -> -130
B17: 45578 | G17: 6 | H17: Energia | I17: 150 | J17: 150 | K17: =+I17-J17 -> 0 | M17: 45 | N17: Caixa Carro J | O17: 0 | P17: =SUMIF(E$10:E$144,"45",D$10:D$144) -> 0 | Q17: =+O17-P17 -> 0
B18: 45579 | G18: 7 | H18: Água | I18: 77 | J18: 77 | K18: =+I18-J18 -> 0 | M18: 46 | N18: Caixa Carro M | O18: 0 | P18: =SUMIF(E$10:E$144,"46",D$10:D$144) -> 0 | Q18: =+O18-P18 -> 0
B19: 45580 | G19: 8 | H19: Gás | I19: 55 | J19: 55 | K19: =+I19-J19 -> 0 | M19: 47 | O19: 0 | P19: =SUMIF(E$10:E$144,"47",D$10:D$144) -> 0 | Q19: =+O19-P19 -> 0
B20: 45581 | G20: 9 | H20: Cartao (Matheus) | I20: 175 | J20: 175 | K20: =+I20-J20 -> 0 | M20: 48 | O20: 0 | P20: =SUMIF(E$10:E$144,"48",D$10:D$144) -> 0 | Q20: =+O20-P20 -> 0
B21: 45582 | G21: 10 | H21: Outrs Dispesas | J21: =SUMIF(E$10:E$144,"10",D$10:D$144) -> 0 | K21: =+I21-J21 -> 0 | M21: 49 | O21: 0 | P21: 0 | Q21: =+O21-P21 -> 0
B22: 45583 | H22: TOTAL | I22: =SUM(I12:I21) -> 3377 | J22: =SUM(J12:J21) -> 1857 | K22: =+I22-J22 -> 1520 | M22: 50 | O22: 0 | P22: 0 | Q22: =+O22-P22 -> 0
B23: 45584 | M23: 51 | N23: Outros Transporte | O23: 0 | P23: =SUMIF(E$10:E$144,"51",D$10:D$144) -> 0 | Q23: =+O23-P23 -> 0
B24: 45585 | H24: ALIMENTAÇÃO | I24: Previsto | J24: Real | K24: Diferença | N24: TOTAL | O24: =SUM(O12:O23) -> 916 | P24: =SUM(P12:P23) -> 428 | Q24: =+O24-P24 -> 488
B25: 45586 | G25: 11 | H25: Supermercado | I25: 450 | J25: 450 | K25: =+I25-J25 -> 0
B26: 45587 | G26: 12 | H26: Restaurante | I26: 140 | J26: 140 | K26: =+I26-J26 -> 0 | N26: EDUCAÇÃO | O26: Previsto | P26: Real | Q26: Diferença
B27: 45588 | G27: 13 | H27: Café \ Almoço | I27: 100 | J27: 250 | K27: =+I27-J27 -> -150 | M27: 52 | N27: Mensalidades | O27: 0 | P27: =SUMIF(E$10:E$144,"52",D$10:D$144) -> 0 | Q27: =+O27-P27 -> 0
B28: 45589 | G28: 14 | H28: Pedidos IFood | I28: 140 | J28: =SUMIF(E$10:E$144,"14",D$10:D$144) -> 0 | K28: =+I28-J28 -> 140 | M28: 53 | N28: Idiomas | O28: 0 | P28: =SUMIF(E$10:E$144,"53",D$10:D$144) -> 0 | Q28: =+O28-P28 -> 0
B29: 45590 | H29: TOTAL | I29: =SUM(I25:I28) -> 830 | J29: =SUM(J25:J28) -> 840 | K29: =+I29-J29 -> -10 | M29: 54 | N29: CNH [Matheus] | O29: 0 | P29: =SUMIF(E$10:E$144,"54",D$10:D$144) -> 0 | Q29: =+O29-P29 -> 0
B30: 45591 | M30: 55 | N30: Cursos | O30: 140 | P30: =SUMIF(E$10:E$144,"55",D$10:D$144) -> 0 | Q30: =+O30-P30 -> 140
B31: 45592 | H31: COMUNICAÇÃO | I31: Previsto | J31: Real | K31: Diferença | M31: 56 | N31: Livros | O31: 0 | P31: =SUMIF(E$10:E$144,"56",D$10:D$144) -> 0 | Q31: =+O31-P31 -> 0
B32: 45593 | G32: 15 | H32: Celular | I32: 45 | J32: 45 | K32: =+I32-J32 -> 0 | M32: 57 | N32: Faculdade [Jhenis] | O32: 0 | P32: =SUMIF(E$10:E$144,"57",D$10:D$144) -> 0 | Q32: =+O32-P32 -> 0
B33: 45594 | G33: 16 | H33: Internet | I33: 89 | J33: 89 | K33: =+I33-J33 -> 0 | M33: 58 | N33: Outros Educação | O33: 0 | P33: =SUMIF(E$10:E$144,"58",D$10:D$144) -> 0 | Q33: =+O33-P33 -> 0
B34: 45595 | G34: 17 | H34: Streaming | I34: 24 | J34: 24 | K34: =+I34-J34 -> 0 | N34: TOTAL | O34: =SUM(O27:O33) -> 140 | P34: =SUM(P27:P33) -> 0 | Q34: =+O34-P34 -> 140
G35: 18 | H35: Netflix | I35: 21.9 | J35: 22 | K35: =+I35-J35 -> -0.1
G36: 19 | H36: Amazon | I36: 10.9 | J36: 11 | K36: =+I36-J36 -> -0.1 | N36: LAZER | O36: Previsto | P36: Real | Q36: Diferença
G37: 20 | H37: Max Plus | I37: 34.5 | J37: 45 | K37: =+I37-J37 -> -10.5 | M37: 60 | N37: Cinema | O37: 450 | P37: =SUMIF(E$10:E$144,"60",D$10:D$144) -> 0 | Q37: =+O37-P37 -> 450
H38: TOTAL | I38: =SUM(I32:I37) -> 225.3 | J38: =SUM(J32:J37) -> 236 | K38: =+I38-J38 -> -10.7 | M38: 61 | N38: Esportes | O38: 0 | P38: =SUMIF(E$10:E$144,"61",D$10:D$144) -> 0 | Q38: =+O38-P38 -> 0
M39: 62 | N39: Shows [Consertos] | O39: 120 | P39: =SUMIF(E$10:E$144,"62",D$10:D$144) -> 0 | Q39: =+O39-P39 -> 120
